[2022-12-12 22:50:33,309][dvadmin.utils.exception.CustomExceptionHandler():46] [ERROR] Traceback (most recent call last):
  File "D:\00-SoftWare\Python3.11\Lib\site-packages\rest_framework\views.py", line 506, in dispatch
    response = handler(request, *args, **kwargs)
               ^^^^^^^^^^^^^^^^^^^^^^^^^^^^^^^^^
  File "F:\django-vue-admin\backend\dvadmin\utils\viewset.py", line 79, in list
    queryset = self.filter_queryset(self.get_queryset())
               ^^^^^^^^^^^^^^^^^^^^^^^^^^^^^^^^^^^^^^^^^
  File "F:\django-vue-admin\backend\dvadmin\utils\viewset.py", line 46, in filter_queryset
    queryset = backend().filter_queryset(self.request, queryset, self)
               ^^^^^^^^^^^^^^^^^^^^^^^^^^^^^^^^^^^^^^^^^^^^^^^^^^^^^^^
  File "F:\django-vue-admin\backend\dvadmin\utils\filters.py", line 305, in filter_queryset
    queryset = queryset.filter(reduce(operator.and_, conditions))
               ^^^^^^^^^^^^^^^^^^^^^^^^^^^^^^^^^^^^^^^^^^^^^^^^^^
  File "D:\00-SoftWare\Python3.11\Lib\site-packages\django\db\models\query.py", line 941, in filter
    return self._filter_or_exclude(False, args, kwargs)
           ^^^^^^^^^^^^^^^^^^^^^^^^^^^^^^^^^^^^^^^^^^^^
  File "D:\00-SoftWare\Python3.11\Lib\site-packages\django\db\models\query.py", line 961, in _filter_or_exclude
    clone._filter_or_exclude_inplace(negate, args, kwargs)
  File "D:\00-SoftWare\Python3.11\Lib\site-packages\django\db\models\query.py", line 968, in _filter_or_exclude_inplace
    self._query.add_q(Q(*args, **kwargs))
  File "D:\00-SoftWare\Python3.11\Lib\site-packages\django\db\models\sql\query.py", line 1391, in add_q
    clause, _ = self._add_q(q_object, self.used_aliases)
                ^^^^^^^^^^^^^^^^^^^^^^^^^^^^^^^^^^^^^^^^
  File "D:\00-SoftWare\Python3.11\Lib\site-packages\django\db\models\sql\query.py", line 1410, in _add_q
    child_clause, needed_inner = self.build_filter(
                                 ^^^^^^^^^^^^^^^^^^
  File "D:\00-SoftWare\Python3.11\Lib\site-packages\django\db\models\sql\query.py", line 1263, in build_filter
    return self._add_q(
           ^^^^^^^^^^^^
  File "D:\00-SoftWare\Python3.11\Lib\site-packages\django\db\models\sql\query.py", line 1410, in _add_q
    child_clause, needed_inner = self.build_filter(
                                 ^^^^^^^^^^^^^^^^^^
  File "D:\00-SoftWare\Python3.11\Lib\site-packages\django\db\models\sql\query.py", line 1345, in build_filter
    condition = self.build_lookup(lookups, col, value)
                ^^^^^^^^^^^^^^^^^^^^^^^^^^^^^^^^^^^^^^
  File "D:\00-SoftWare\Python3.11\Lib\site-packages\django\db\models\sql\query.py", line 1176, in build_lookup
    lhs = self.try_transform(lhs, name)
          ^^^^^^^^^^^^^^^^^^^^^^^^^^^^^
  File "D:\00-SoftWare\Python3.11\Lib\site-packages\django\db\models\sql\query.py", line 1224, in try_transform
    raise FieldError(
django.core.exceptions.FieldError: Unsupported lookup 'icontains' for CharField or join on the field not permitted, perhaps you meant icontains or contains?

[2022-12-12 22:50:40,204][dvadmin.utils.exception.CustomExceptionHandler():46] [ERROR] Traceback (most recent call last):
  File "D:\00-SoftWare\Python3.11\Lib\site-packages\rest_framework\views.py", line 506, in dispatch
    response = handler(request, *args, **kwargs)
               ^^^^^^^^^^^^^^^^^^^^^^^^^^^^^^^^^
  File "F:\django-vue-admin\backend\dvadmin\utils\viewset.py", line 79, in list
    queryset = self.filter_queryset(self.get_queryset())
               ^^^^^^^^^^^^^^^^^^^^^^^^^^^^^^^^^^^^^^^^^
  File "F:\django-vue-admin\backend\dvadmin\utils\viewset.py", line 46, in filter_queryset
    queryset = backend().filter_queryset(self.request, queryset, self)
               ^^^^^^^^^^^^^^^^^^^^^^^^^^^^^^^^^^^^^^^^^^^^^^^^^^^^^^^
  File "F:\django-vue-admin\backend\dvadmin\utils\filters.py", line 305, in filter_queryset
    queryset = queryset.filter(reduce(operator.and_, conditions))
               ^^^^^^^^^^^^^^^^^^^^^^^^^^^^^^^^^^^^^^^^^^^^^^^^^^
  File "D:\00-SoftWare\Python3.11\Lib\site-packages\django\db\models\query.py", line 941, in filter
    return self._filter_or_exclude(False, args, kwargs)
           ^^^^^^^^^^^^^^^^^^^^^^^^^^^^^^^^^^^^^^^^^^^^
  File "D:\00-SoftWare\Python3.11\Lib\site-packages\django\db\models\query.py", line 961, in _filter_or_exclude
    clone._filter_or_exclude_inplace(negate, args, kwargs)
  File "D:\00-SoftWare\Python3.11\Lib\site-packages\django\db\models\query.py", line 968, in _filter_or_exclude_inplace
    self._query.add_q(Q(*args, **kwargs))
  File "D:\00-SoftWare\Python3.11\Lib\site-packages\django\db\models\sql\query.py", line 1391, in add_q
    clause, _ = self._add_q(q_object, self.used_aliases)
                ^^^^^^^^^^^^^^^^^^^^^^^^^^^^^^^^^^^^^^^^
  File "D:\00-SoftWare\Python3.11\Lib\site-packages\django\db\models\sql\query.py", line 1410, in _add_q
    child_clause, needed_inner = self.build_filter(
                                 ^^^^^^^^^^^^^^^^^^
  File "D:\00-SoftWare\Python3.11\Lib\site-packages\django\db\models\sql\query.py", line 1263, in build_filter
    return self._add_q(
           ^^^^^^^^^^^^
  File "D:\00-SoftWare\Python3.11\Lib\site-packages\django\db\models\sql\query.py", line 1410, in _add_q
    child_clause, needed_inner = self.build_filter(
                                 ^^^^^^^^^^^^^^^^^^
  File "D:\00-SoftWare\Python3.11\Lib\site-packages\django\db\models\sql\query.py", line 1345, in build_filter
    condition = self.build_lookup(lookups, col, value)
                ^^^^^^^^^^^^^^^^^^^^^^^^^^^^^^^^^^^^^^
  File "D:\00-SoftWare\Python3.11\Lib\site-packages\django\db\models\sql\query.py", line 1176, in build_lookup
    lhs = self.try_transform(lhs, name)
          ^^^^^^^^^^^^^^^^^^^^^^^^^^^^^
  File "D:\00-SoftWare\Python3.11\Lib\site-packages\django\db\models\sql\query.py", line 1224, in try_transform
    raise FieldError(
django.core.exceptions.FieldError: Unsupported lookup 'icontains' for CharField or join on the field not permitted, perhaps you meant icontains or contains?

[2022-12-12 22:50:48,649][dvadmin.utils.exception.CustomExceptionHandler():46] [ERROR] Traceback (most recent call last):
  File "D:\00-SoftWare\Python3.11\Lib\site-packages\rest_framework\views.py", line 506, in dispatch
    response = handler(request, *args, **kwargs)
               ^^^^^^^^^^^^^^^^^^^^^^^^^^^^^^^^^
  File "F:\django-vue-admin\backend\dvadmin\utils\viewset.py", line 79, in list
    queryset = self.filter_queryset(self.get_queryset())
               ^^^^^^^^^^^^^^^^^^^^^^^^^^^^^^^^^^^^^^^^^
  File "F:\django-vue-admin\backend\dvadmin\utils\viewset.py", line 46, in filter_queryset
    queryset = backend().filter_queryset(self.request, queryset, self)
               ^^^^^^^^^^^^^^^^^^^^^^^^^^^^^^^^^^^^^^^^^^^^^^^^^^^^^^^
  File "F:\django-vue-admin\backend\dvadmin\utils\filters.py", line 305, in filter_queryset
    queryset = queryset.filter(reduce(operator.and_, conditions))
               ^^^^^^^^^^^^^^^^^^^^^^^^^^^^^^^^^^^^^^^^^^^^^^^^^^
  File "D:\00-SoftWare\Python3.11\Lib\site-packages\django\db\models\query.py", line 941, in filter
    return self._filter_or_exclude(False, args, kwargs)
           ^^^^^^^^^^^^^^^^^^^^^^^^^^^^^^^^^^^^^^^^^^^^
  File "D:\00-SoftWare\Python3.11\Lib\site-packages\django\db\models\query.py", line 961, in _filter_or_exclude
    clone._filter_or_exclude_inplace(negate, args, kwargs)
  File "D:\00-SoftWare\Python3.11\Lib\site-packages\django\db\models\query.py", line 968, in _filter_or_exclude_inplace
    self._query.add_q(Q(*args, **kwargs))
  File "D:\00-SoftWare\Python3.11\Lib\site-packages\django\db\models\sql\query.py", line 1391, in add_q
    clause, _ = self._add_q(q_object, self.used_aliases)
                ^^^^^^^^^^^^^^^^^^^^^^^^^^^^^^^^^^^^^^^^
  File "D:\00-SoftWare\Python3.11\Lib\site-packages\django\db\models\sql\query.py", line 1410, in _add_q
    child_clause, needed_inner = self.build_filter(
                                 ^^^^^^^^^^^^^^^^^^
  File "D:\00-SoftWare\Python3.11\Lib\site-packages\django\db\models\sql\query.py", line 1263, in build_filter
    return self._add_q(
           ^^^^^^^^^^^^
  File "D:\00-SoftWare\Python3.11\Lib\site-packages\django\db\models\sql\query.py", line 1410, in _add_q
    child_clause, needed_inner = self.build_filter(
                                 ^^^^^^^^^^^^^^^^^^
  File "D:\00-SoftWare\Python3.11\Lib\site-packages\django\db\models\sql\query.py", line 1345, in build_filter
    condition = self.build_lookup(lookups, col, value)
                ^^^^^^^^^^^^^^^^^^^^^^^^^^^^^^^^^^^^^^
  File "D:\00-SoftWare\Python3.11\Lib\site-packages\django\db\models\sql\query.py", line 1176, in build_lookup
    lhs = self.try_transform(lhs, name)
          ^^^^^^^^^^^^^^^^^^^^^^^^^^^^^
  File "D:\00-SoftWare\Python3.11\Lib\site-packages\django\db\models\sql\query.py", line 1224, in try_transform
    raise FieldError(
django.core.exceptions.FieldError: Unsupported lookup 'icontains' for CharField or join on the field not permitted, perhaps you meant icontains or contains?

[2022-12-12 22:59:00,275][dvadmin.utils.exception.CustomExceptionHandler():46] [ERROR] Traceback (most recent call last):
  File "D:\00-SoftWare\Python3.11\Lib\site-packages\rest_framework\views.py", line 506, in dispatch
    response = handler(request, *args, **kwargs)
               ^^^^^^^^^^^^^^^^^^^^^^^^^^^^^^^^^
  File "F:\django-vue-admin\backend\dvadmin\utils\viewset.py", line 79, in list
    queryset = self.filter_queryset(self.get_queryset())
               ^^^^^^^^^^^^^^^^^^^^^^^^^^^^^^^^^^^^^^^^^
  File "F:\django-vue-admin\backend\dvadmin\utils\viewset.py", line 46, in filter_queryset
    queryset = backend().filter_queryset(self.request, queryset, self)
               ^^^^^^^^^^^^^^^^^^^^^^^^^^^^^^^^^^^^^^^^^^^^^^^^^^^^^^^
  File "F:\django-vue-admin\backend\dvadmin\utils\filters.py", line 305, in filter_queryset
    queryset = queryset.filter(reduce(operator.and_, conditions))
               ^^^^^^^^^^^^^^^^^^^^^^^^^^^^^^^^^^^^^^^^^^^^^^^^^^
  File "D:\00-SoftWare\Python3.11\Lib\site-packages\django\db\models\query.py", line 941, in filter
    return self._filter_or_exclude(False, args, kwargs)
           ^^^^^^^^^^^^^^^^^^^^^^^^^^^^^^^^^^^^^^^^^^^^
  File "D:\00-SoftWare\Python3.11\Lib\site-packages\django\db\models\query.py", line 961, in _filter_or_exclude
    clone._filter_or_exclude_inplace(negate, args, kwargs)
  File "D:\00-SoftWare\Python3.11\Lib\site-packages\django\db\models\query.py", line 968, in _filter_or_exclude_inplace
    self._query.add_q(Q(*args, **kwargs))
  File "D:\00-SoftWare\Python3.11\Lib\site-packages\django\db\models\sql\query.py", line 1391, in add_q
    clause, _ = self._add_q(q_object, self.used_aliases)
                ^^^^^^^^^^^^^^^^^^^^^^^^^^^^^^^^^^^^^^^^
  File "D:\00-SoftWare\Python3.11\Lib\site-packages\django\db\models\sql\query.py", line 1410, in _add_q
    child_clause, needed_inner = self.build_filter(
                                 ^^^^^^^^^^^^^^^^^^
  File "D:\00-SoftWare\Python3.11\Lib\site-packages\django\db\models\sql\query.py", line 1263, in build_filter
    return self._add_q(
           ^^^^^^^^^^^^
  File "D:\00-SoftWare\Python3.11\Lib\site-packages\django\db\models\sql\query.py", line 1410, in _add_q
    child_clause, needed_inner = self.build_filter(
                                 ^^^^^^^^^^^^^^^^^^
  File "D:\00-SoftWare\Python3.11\Lib\site-packages\django\db\models\sql\query.py", line 1345, in build_filter
    condition = self.build_lookup(lookups, col, value)
                ^^^^^^^^^^^^^^^^^^^^^^^^^^^^^^^^^^^^^^
  File "D:\00-SoftWare\Python3.11\Lib\site-packages\django\db\models\sql\query.py", line 1176, in build_lookup
    lhs = self.try_transform(lhs, name)
          ^^^^^^^^^^^^^^^^^^^^^^^^^^^^^
  File "D:\00-SoftWare\Python3.11\Lib\site-packages\django\db\models\sql\query.py", line 1224, in try_transform
    raise FieldError(
django.core.exceptions.FieldError: Unsupported lookup 'icontains' for CharField or join on the field not permitted, perhaps you meant icontains or contains?

[2022-12-12 23:01:37,542][dvadmin.utils.exception.CustomExceptionHandler():46] [ERROR] Traceback (most recent call last):
  File "D:\00-SoftWare\Python3.11\Lib\site-packages\rest_framework\views.py", line 506, in dispatch
    response = handler(request, *args, **kwargs)
               ^^^^^^^^^^^^^^^^^^^^^^^^^^^^^^^^^
  File "F:\django-vue-admin\backend\dvadmin\utils\viewset.py", line 79, in list
    queryset = self.filter_queryset(self.get_queryset())
               ^^^^^^^^^^^^^^^^^^^^^^^^^^^^^^^^^^^^^^^^^
  File "F:\django-vue-admin\backend\dvadmin\utils\viewset.py", line 46, in filter_queryset
    queryset = backend().filter_queryset(self.request, queryset, self)
               ^^^^^^^^^^^^^^^^^^^^^^^^^^^^^^^^^^^^^^^^^^^^^^^^^^^^^^^
  File "F:\django-vue-admin\backend\dvadmin\utils\filters.py", line 305, in filter_queryset
    queryset = queryset.filter(reduce(operator.and_, conditions))
               ^^^^^^^^^^^^^^^^^^^^^^^^^^^^^^^^^^^^^^^^^^^^^^^^^^
  File "D:\00-SoftWare\Python3.11\Lib\site-packages\django\db\models\query.py", line 941, in filter
    return self._filter_or_exclude(False, args, kwargs)
           ^^^^^^^^^^^^^^^^^^^^^^^^^^^^^^^^^^^^^^^^^^^^
  File "D:\00-SoftWare\Python3.11\Lib\site-packages\django\db\models\query.py", line 961, in _filter_or_exclude
    clone._filter_or_exclude_inplace(negate, args, kwargs)
  File "D:\00-SoftWare\Python3.11\Lib\site-packages\django\db\models\query.py", line 968, in _filter_or_exclude_inplace
    self._query.add_q(Q(*args, **kwargs))
  File "D:\00-SoftWare\Python3.11\Lib\site-packages\django\db\models\sql\query.py", line 1391, in add_q
    clause, _ = self._add_q(q_object, self.used_aliases)
                ^^^^^^^^^^^^^^^^^^^^^^^^^^^^^^^^^^^^^^^^
  File "D:\00-SoftWare\Python3.11\Lib\site-packages\django\db\models\sql\query.py", line 1410, in _add_q
    child_clause, needed_inner = self.build_filter(
                                 ^^^^^^^^^^^^^^^^^^
  File "D:\00-SoftWare\Python3.11\Lib\site-packages\django\db\models\sql\query.py", line 1263, in build_filter
    return self._add_q(
           ^^^^^^^^^^^^
  File "D:\00-SoftWare\Python3.11\Lib\site-packages\django\db\models\sql\query.py", line 1410, in _add_q
    child_clause, needed_inner = self.build_filter(
                                 ^^^^^^^^^^^^^^^^^^
  File "D:\00-SoftWare\Python3.11\Lib\site-packages\django\db\models\sql\query.py", line 1345, in build_filter
    condition = self.build_lookup(lookups, col, value)
                ^^^^^^^^^^^^^^^^^^^^^^^^^^^^^^^^^^^^^^
  File "D:\00-SoftWare\Python3.11\Lib\site-packages\django\db\models\sql\query.py", line 1176, in build_lookup
    lhs = self.try_transform(lhs, name)
          ^^^^^^^^^^^^^^^^^^^^^^^^^^^^^
  File "D:\00-SoftWare\Python3.11\Lib\site-packages\django\db\models\sql\query.py", line 1224, in try_transform
    raise FieldError(
django.core.exceptions.FieldError: Unsupported lookup 'icontains' for CharField or join on the field not permitted, perhaps you meant icontains or contains?

[2022-12-12 23:02:21,226][dvadmin.utils.exception.CustomExceptionHandler():46] [ERROR] Traceback (most recent call last):
  File "D:\00-SoftWare\Python3.11\Lib\site-packages\rest_framework\views.py", line 506, in dispatch
    response = handler(request, *args, **kwargs)
               ^^^^^^^^^^^^^^^^^^^^^^^^^^^^^^^^^
  File "F:\django-vue-admin\backend\dvadmin\utils\viewset.py", line 79, in list
    queryset = self.filter_queryset(self.get_queryset())
               ^^^^^^^^^^^^^^^^^^^^^^^^^^^^^^^^^^^^^^^^^
  File "F:\django-vue-admin\backend\dvadmin\utils\viewset.py", line 46, in filter_queryset
    queryset = backend().filter_queryset(self.request, queryset, self)
               ^^^^^^^^^^^^^^^^^^^^^^^^^^^^^^^^^^^^^^^^^^^^^^^^^^^^^^^
  File "F:\django-vue-admin\backend\dvadmin\utils\filters.py", line 305, in filter_queryset
    queryset = queryset.filter(reduce(operator.and_, conditions))
               ^^^^^^^^^^^^^^^^^^^^^^^^^^^^^^^^^^^^^^^^^^^^^^^^^^
  File "D:\00-SoftWare\Python3.11\Lib\site-packages\django\db\models\query.py", line 941, in filter
    return self._filter_or_exclude(False, args, kwargs)
           ^^^^^^^^^^^^^^^^^^^^^^^^^^^^^^^^^^^^^^^^^^^^
  File "D:\00-SoftWare\Python3.11\Lib\site-packages\django\db\models\query.py", line 961, in _filter_or_exclude
    clone._filter_or_exclude_inplace(negate, args, kwargs)
  File "D:\00-SoftWare\Python3.11\Lib\site-packages\django\db\models\query.py", line 968, in _filter_or_exclude_inplace
    self._query.add_q(Q(*args, **kwargs))
  File "D:\00-SoftWare\Python3.11\Lib\site-packages\django\db\models\sql\query.py", line 1391, in add_q
    clause, _ = self._add_q(q_object, self.used_aliases)
                ^^^^^^^^^^^^^^^^^^^^^^^^^^^^^^^^^^^^^^^^
  File "D:\00-SoftWare\Python3.11\Lib\site-packages\django\db\models\sql\query.py", line 1410, in _add_q
    child_clause, needed_inner = self.build_filter(
                                 ^^^^^^^^^^^^^^^^^^
  File "D:\00-SoftWare\Python3.11\Lib\site-packages\django\db\models\sql\query.py", line 1263, in build_filter
    return self._add_q(
           ^^^^^^^^^^^^
  File "D:\00-SoftWare\Python3.11\Lib\site-packages\django\db\models\sql\query.py", line 1410, in _add_q
    child_clause, needed_inner = self.build_filter(
                                 ^^^^^^^^^^^^^^^^^^
  File "D:\00-SoftWare\Python3.11\Lib\site-packages\django\db\models\sql\query.py", line 1345, in build_filter
    condition = self.build_lookup(lookups, col, value)
                ^^^^^^^^^^^^^^^^^^^^^^^^^^^^^^^^^^^^^^
  File "D:\00-SoftWare\Python3.11\Lib\site-packages\django\db\models\sql\query.py", line 1176, in build_lookup
    lhs = self.try_transform(lhs, name)
          ^^^^^^^^^^^^^^^^^^^^^^^^^^^^^
  File "D:\00-SoftWare\Python3.11\Lib\site-packages\django\db\models\sql\query.py", line 1224, in try_transform
    raise FieldError(
django.core.exceptions.FieldError: Unsupported lookup 'icontains' for CharField or join on the field not permitted, perhaps you meant icontains or contains?

[2022-12-13 15:00:52,587][dvadmin.utils.exception.CustomExceptionHandler():46] [ERROR] Traceback (most recent call last):
  File "D:\00-SoftWare\Python3.11\Lib\site-packages\rest_framework\views.py", line 506, in dispatch
    response = handler(request, *args, **kwargs)
               ^^^^^^^^^^^^^^^^^^^^^^^^^^^^^^^^^
  File "F:\django-vue-admin\backend\dvadmin\utils\viewset.py", line 79, in list
    queryset = self.filter_queryset(self.get_queryset())
               ^^^^^^^^^^^^^^^^^^^^^^^^^^^^^^^^^^^^^^^^^
  File "F:\django-vue-admin\backend\dvadmin\utils\viewset.py", line 46, in filter_queryset
    queryset = backend().filter_queryset(self.request, queryset, self)
               ^^^^^^^^^^^^^^^^^^^^^^^^^^^^^^^^^^^^^^^^^^^^^^^^^^^^^^^
  File "F:\django-vue-admin\backend\dvadmin\utils\filters.py", line 305, in filter_queryset
    queryset = queryset.filter(reduce(operator.and_, conditions))
               ^^^^^^^^^^^^^^^^^^^^^^^^^^^^^^^^^^^^^^^^^^^^^^^^^^
  File "D:\00-SoftWare\Python3.11\Lib\site-packages\django\db\models\query.py", line 941, in filter
    return self._filter_or_exclude(False, args, kwargs)
           ^^^^^^^^^^^^^^^^^^^^^^^^^^^^^^^^^^^^^^^^^^^^
  File "D:\00-SoftWare\Python3.11\Lib\site-packages\django\db\models\query.py", line 961, in _filter_or_exclude
    clone._filter_or_exclude_inplace(negate, args, kwargs)
  File "D:\00-SoftWare\Python3.11\Lib\site-packages\django\db\models\query.py", line 968, in _filter_or_exclude_inplace
    self._query.add_q(Q(*args, **kwargs))
  File "D:\00-SoftWare\Python3.11\Lib\site-packages\django\db\models\sql\query.py", line 1391, in add_q
    clause, _ = self._add_q(q_object, self.used_aliases)
                ^^^^^^^^^^^^^^^^^^^^^^^^^^^^^^^^^^^^^^^^
  File "D:\00-SoftWare\Python3.11\Lib\site-packages\django\db\models\sql\query.py", line 1410, in _add_q
    child_clause, needed_inner = self.build_filter(
                                 ^^^^^^^^^^^^^^^^^^
  File "D:\00-SoftWare\Python3.11\Lib\site-packages\django\db\models\sql\query.py", line 1263, in build_filter
    return self._add_q(
           ^^^^^^^^^^^^
  File "D:\00-SoftWare\Python3.11\Lib\site-packages\django\db\models\sql\query.py", line 1410, in _add_q
    child_clause, needed_inner = self.build_filter(
                                 ^^^^^^^^^^^^^^^^^^
  File "D:\00-SoftWare\Python3.11\Lib\site-packages\django\db\models\sql\query.py", line 1345, in build_filter
    condition = self.build_lookup(lookups, col, value)
                ^^^^^^^^^^^^^^^^^^^^^^^^^^^^^^^^^^^^^^
  File "D:\00-SoftWare\Python3.11\Lib\site-packages\django\db\models\sql\query.py", line 1176, in build_lookup
    lhs = self.try_transform(lhs, name)
          ^^^^^^^^^^^^^^^^^^^^^^^^^^^^^
  File "D:\00-SoftWare\Python3.11\Lib\site-packages\django\db\models\sql\query.py", line 1224, in try_transform
    raise FieldError(
django.core.exceptions.FieldError: Unsupported lookup 'icontains' for CharField or join on the field not permitted, perhaps you meant icontains or contains?

[2022-12-13 16:10:32,993][dvadmin.utils.exception.CustomExceptionHandler():46] [ERROR] Traceback (most recent call last):
  File "D:\00-SoftWare\Python3.11\Lib\site-packages\rest_framework\views.py", line 506, in dispatch
    response = handler(request, *args, **kwargs)
               ^^^^^^^^^^^^^^^^^^^^^^^^^^^^^^^^^
  File "D:\00-SoftWare\Python3.11\Lib\contextlib.py", line 81, in inner
    return func(*args, **kwds)
           ^^^^^^^^^^^^^^^^^^^
  File "F:\django-vue-admin\backend\dvadmin\utils\import_export_mixin.py", line 147, in import_data
    data = import_to_data(request.data.get("url"), self.import_field_dict, m2m_fields)
           ^^^^^^^^^^^^^^^^^^^^^^^^^^^^^^^^^^^^^^^^^^^^^^^^^^^^^^^^^^^^^^^^^^^^^^^^^^^
  File "F:\django-vue-admin\backend\dvadmin\utils\import_export.py", line 19, in import_to_data
    workbook = openpyxl.load_workbook(file_path_dir)
               ^^^^^^^^^^^^^^^^^^^^^^^^^^^^^^^^^^^^^
  File "D:\00-SoftWare\Python3.11\Lib\site-packages\openpyxl\reader\excel.py", line 315, in load_workbook
    reader = ExcelReader(filename, read_only, keep_vba,
             ^^^^^^^^^^^^^^^^^^^^^^^^^^^^^^^^^^^^^^^^^^
  File "D:\00-SoftWare\Python3.11\Lib\site-packages\openpyxl\reader\excel.py", line 124, in __init__
    self.archive = _validate_archive(fn)
                   ^^^^^^^^^^^^^^^^^^^^^
  File "D:\00-SoftWare\Python3.11\Lib\site-packages\openpyxl\reader\excel.py", line 94, in _validate_archive
    raise InvalidFileException(msg)
openpyxl.utils.exceptions.InvalidFileException: openpyxl does not support the old .xls file format, please use xlrd to read this file, or convert it to the more recent .xlsx file format.

[2022-12-13 16:10:45,859][dvadmin.utils.exception.CustomExceptionHandler():46] [ERROR] Traceback (most recent call last):
  File "D:\00-SoftWare\Python3.11\Lib\site-packages\rest_framework\views.py", line 506, in dispatch
    response = handler(request, *args, **kwargs)
               ^^^^^^^^^^^^^^^^^^^^^^^^^^^^^^^^^
  File "D:\00-SoftWare\Python3.11\Lib\contextlib.py", line 81, in inner
    return func(*args, **kwds)
           ^^^^^^^^^^^^^^^^^^^
  File "F:\django-vue-admin\backend\dvadmin\utils\import_export_mixin.py", line 147, in import_data
    data = import_to_data(request.data.get("url"), self.import_field_dict, m2m_fields)
           ^^^^^^^^^^^^^^^^^^^^^^^^^^^^^^^^^^^^^^^^^^^^^^^^^^^^^^^^^^^^^^^^^^^^^^^^^^^
  File "F:\django-vue-admin\backend\dvadmin\utils\import_export.py", line 19, in import_to_data
    workbook = openpyxl.load_workbook(file_path_dir)
               ^^^^^^^^^^^^^^^^^^^^^^^^^^^^^^^^^^^^^
  File "D:\00-SoftWare\Python3.11\Lib\site-packages\openpyxl\reader\excel.py", line 315, in load_workbook
    reader = ExcelReader(filename, read_only, keep_vba,
             ^^^^^^^^^^^^^^^^^^^^^^^^^^^^^^^^^^^^^^^^^^
  File "D:\00-SoftWare\Python3.11\Lib\site-packages\openpyxl\reader\excel.py", line 124, in __init__
    self.archive = _validate_archive(fn)
                   ^^^^^^^^^^^^^^^^^^^^^
  File "D:\00-SoftWare\Python3.11\Lib\site-packages\openpyxl\reader\excel.py", line 94, in _validate_archive
    raise InvalidFileException(msg)
openpyxl.utils.exceptions.InvalidFileException: openpyxl does not support the old .xls file format, please use xlrd to read this file, or convert it to the more recent .xlsx file format.

[2022-12-13 16:13:26,997][dvadmin.utils.exception.CustomExceptionHandler():46] [ERROR] Traceback (most recent call last):
  File "D:\00-SoftWare\Python3.11\Lib\site-packages\django\db\models\fields\__init__.py", line 1823, in get_prep_value
    return int(value)
           ^^^^^^^^^^
ValueError: invalid literal for int() with base 10: 'import'

The above exception was the direct cause of the following exception:

Traceback (most recent call last):
  File "D:\00-SoftWare\Python3.11\Lib\site-packages\rest_framework\generics.py", line 19, in get_object_or_404
    return _get_object_or_404(queryset, *filter_args, **filter_kwargs)
           ^^^^^^^^^^^^^^^^^^^^^^^^^^^^^^^^^^^^^^^^^^^^^^^^^^^^^^^^^^^
  File "D:\00-SoftWare\Python3.11\Lib\site-packages\django\shortcuts.py", line 76, in get_object_or_404
    return queryset.get(*args, **kwargs)
           ^^^^^^^^^^^^^^^^^^^^^^^^^^^^^
  File "D:\00-SoftWare\Python3.11\Lib\site-packages\django\db\models\query.py", line 424, in get
    clone = self._chain() if self.query.combinator else self.filter(*args, **kwargs)
                                                        ^^^^^^^^^^^^^^^^^^^^^^^^^^^^
  File "D:\00-SoftWare\Python3.11\Lib\site-packages\django\db\models\query.py", line 941, in filter
    return self._filter_or_exclude(False, args, kwargs)
           ^^^^^^^^^^^^^^^^^^^^^^^^^^^^^^^^^^^^^^^^^^^^
  File "D:\00-SoftWare\Python3.11\Lib\site-packages\django\db\models\query.py", line 961, in _filter_or_exclude
    clone._filter_or_exclude_inplace(negate, args, kwargs)
  File "D:\00-SoftWare\Python3.11\Lib\site-packages\django\db\models\query.py", line 968, in _filter_or_exclude_inplace
    self._query.add_q(Q(*args, **kwargs))
  File "D:\00-SoftWare\Python3.11\Lib\site-packages\django\db\models\sql\query.py", line 1391, in add_q
    clause, _ = self._add_q(q_object, self.used_aliases)
                ^^^^^^^^^^^^^^^^^^^^^^^^^^^^^^^^^^^^^^^^
  File "D:\00-SoftWare\Python3.11\Lib\site-packages\django\db\models\sql\query.py", line 1410, in _add_q
    child_clause, needed_inner = self.build_filter(
                                 ^^^^^^^^^^^^^^^^^^
  File "D:\00-SoftWare\Python3.11\Lib\site-packages\django\db\models\sql\query.py", line 1345, in build_filter
    condition = self.build_lookup(lookups, col, value)
                ^^^^^^^^^^^^^^^^^^^^^^^^^^^^^^^^^^^^^^
  File "D:\00-SoftWare\Python3.11\Lib\site-packages\django\db\models\sql\query.py", line 1191, in build_lookup
    lookup = lookup_class(lhs, rhs)
             ^^^^^^^^^^^^^^^^^^^^^^
  File "D:\00-SoftWare\Python3.11\Lib\site-packages\django\db\models\lookups.py", line 25, in __init__
    self.rhs = self.get_prep_lookup()
               ^^^^^^^^^^^^^^^^^^^^^^
  File "D:\00-SoftWare\Python3.11\Lib\site-packages\django\db\models\lookups.py", line 77, in get_prep_lookup
    return self.lhs.output_field.get_prep_value(self.rhs)
           ^^^^^^^^^^^^^^^^^^^^^^^^^^^^^^^^^^^^^^^^^^^^^^
  File "D:\00-SoftWare\Python3.11\Lib\site-packages\django\db\models\fields\__init__.py", line 1825, in get_prep_value
    raise e.__class__(
ValueError: Field 'id' expected a number but got 'import'.

During handling of the above exception, another exception occurred:

Traceback (most recent call last):
  File "D:\00-SoftWare\Python3.11\Lib\site-packages\rest_framework\views.py", line 506, in dispatch
    response = handler(request, *args, **kwargs)
               ^^^^^^^^^^^^^^^^^^^^^^^^^^^^^^^^^
  File "F:\django-vue-admin\backend\dvadmin\utils\viewset.py", line 88, in retrieve
    instance = self.get_object()
               ^^^^^^^^^^^^^^^^^
  File "D:\00-SoftWare\Python3.11\Lib\site-packages\rest_framework\generics.py", line 96, in get_object
    obj = get_object_or_404(queryset, **filter_kwargs)
          ^^^^^^^^^^^^^^^^^^^^^^^^^^^^^^^^^^^^^^^^^^^^
  File "D:\00-SoftWare\Python3.11\Lib\site-packages\rest_framework\generics.py", line 21, in get_object_or_404
    raise Http404
django.http.response.Http404

[2022-12-13 16:18:00,093][dvadmin.utils.exception.CustomExceptionHandler():46] [ERROR] Traceback (most recent call last):
  File "D:\00-SoftWare\Python3.11\Lib\site-packages\django\db\models\fields\__init__.py", line 1823, in get_prep_value
    return int(value)
           ^^^^^^^^^^
ValueError: invalid literal for int() with base 10: 'import'

The above exception was the direct cause of the following exception:

Traceback (most recent call last):
  File "D:\00-SoftWare\Python3.11\Lib\site-packages\rest_framework\generics.py", line 19, in get_object_or_404
    return _get_object_or_404(queryset, *filter_args, **filter_kwargs)
           ^^^^^^^^^^^^^^^^^^^^^^^^^^^^^^^^^^^^^^^^^^^^^^^^^^^^^^^^^^^
  File "D:\00-SoftWare\Python3.11\Lib\site-packages\django\shortcuts.py", line 76, in get_object_or_404
    return queryset.get(*args, **kwargs)
           ^^^^^^^^^^^^^^^^^^^^^^^^^^^^^
  File "D:\00-SoftWare\Python3.11\Lib\site-packages\django\db\models\query.py", line 424, in get
    clone = self._chain() if self.query.combinator else self.filter(*args, **kwargs)
                                                        ^^^^^^^^^^^^^^^^^^^^^^^^^^^^
  File "D:\00-SoftWare\Python3.11\Lib\site-packages\django\db\models\query.py", line 941, in filter
    return self._filter_or_exclude(False, args, kwargs)
           ^^^^^^^^^^^^^^^^^^^^^^^^^^^^^^^^^^^^^^^^^^^^
  File "D:\00-SoftWare\Python3.11\Lib\site-packages\django\db\models\query.py", line 961, in _filter_or_exclude
    clone._filter_or_exclude_inplace(negate, args, kwargs)
  File "D:\00-SoftWare\Python3.11\Lib\site-packages\django\db\models\query.py", line 968, in _filter_or_exclude_inplace
    self._query.add_q(Q(*args, **kwargs))
  File "D:\00-SoftWare\Python3.11\Lib\site-packages\django\db\models\sql\query.py", line 1391, in add_q
    clause, _ = self._add_q(q_object, self.used_aliases)
                ^^^^^^^^^^^^^^^^^^^^^^^^^^^^^^^^^^^^^^^^
  File "D:\00-SoftWare\Python3.11\Lib\site-packages\django\db\models\sql\query.py", line 1410, in _add_q
    child_clause, needed_inner = self.build_filter(
                                 ^^^^^^^^^^^^^^^^^^
  File "D:\00-SoftWare\Python3.11\Lib\site-packages\django\db\models\sql\query.py", line 1345, in build_filter
    condition = self.build_lookup(lookups, col, value)
                ^^^^^^^^^^^^^^^^^^^^^^^^^^^^^^^^^^^^^^
  File "D:\00-SoftWare\Python3.11\Lib\site-packages\django\db\models\sql\query.py", line 1191, in build_lookup
    lookup = lookup_class(lhs, rhs)
             ^^^^^^^^^^^^^^^^^^^^^^
  File "D:\00-SoftWare\Python3.11\Lib\site-packages\django\db\models\lookups.py", line 25, in __init__
    self.rhs = self.get_prep_lookup()
               ^^^^^^^^^^^^^^^^^^^^^^
  File "D:\00-SoftWare\Python3.11\Lib\site-packages\django\db\models\lookups.py", line 77, in get_prep_lookup
    return self.lhs.output_field.get_prep_value(self.rhs)
           ^^^^^^^^^^^^^^^^^^^^^^^^^^^^^^^^^^^^^^^^^^^^^^
  File "D:\00-SoftWare\Python3.11\Lib\site-packages\django\db\models\fields\__init__.py", line 1825, in get_prep_value
    raise e.__class__(
ValueError: Field 'id' expected a number but got 'import'.

During handling of the above exception, another exception occurred:

Traceback (most recent call last):
  File "D:\00-SoftWare\Python3.11\Lib\site-packages\rest_framework\views.py", line 506, in dispatch
    response = handler(request, *args, **kwargs)
               ^^^^^^^^^^^^^^^^^^^^^^^^^^^^^^^^^
  File "F:\django-vue-admin\backend\dvadmin\utils\viewset.py", line 88, in retrieve
    instance = self.get_object()
               ^^^^^^^^^^^^^^^^^
  File "D:\00-SoftWare\Python3.11\Lib\site-packages\rest_framework\generics.py", line 96, in get_object
    obj = get_object_or_404(queryset, **filter_kwargs)
          ^^^^^^^^^^^^^^^^^^^^^^^^^^^^^^^^^^^^^^^^^^^^
  File "D:\00-SoftWare\Python3.11\Lib\site-packages\rest_framework\generics.py", line 21, in get_object_or_404
    raise Http404
django.http.response.Http404

[2022-12-13 16:29:50,015][dvadmin.utils.exception.CustomExceptionHandler():46] [ERROR] Traceback (most recent call last):
  File "D:\00-SoftWare\Python3.11\Lib\site-packages\rest_framework\views.py", line 506, in dispatch
    response = handler(request, *args, **kwargs)
               ^^^^^^^^^^^^^^^^^^^^^^^^^^^^^^^^^
  File "D:\00-SoftWare\Python3.11\Lib\contextlib.py", line 81, in inner
    return func(*args, **kwds)
           ^^^^^^^^^^^^^^^^^^^
  File "F:\django-vue-admin\backend\dvadmin\utils\import_export_mixin.py", line 70, in import_data
    assert self.import_field_dict, "'%s' 请配置对应的导出模板字段。" % self.__class__.__name__
AssertionError: 'EmployeeViewSet' 请配置对应的导出模板字段。

[2022-12-13 16:30:34,868][dvadmin.utils.exception.CustomExceptionHandler():46] [ERROR] Traceback (most recent call last):
  File "D:\00-SoftWare\Python3.11\Lib\site-packages\rest_framework\views.py", line 506, in dispatch
    response = handler(request, *args, **kwargs)
               ^^^^^^^^^^^^^^^^^^^^^^^^^^^^^^^^^
  File "D:\00-SoftWare\Python3.11\Lib\contextlib.py", line 81, in inner
    return func(*args, **kwds)
           ^^^^^^^^^^^^^^^^^^^
  File "F:\django-vue-admin\backend\dvadmin\utils\import_export_mixin.py", line 70, in import_data
    assert self.import_field_dict, "'%s' 请配置对应的导出模板字段。" % self.__class__.__name__
AssertionError: 'EmployeeViewSet' 请配置对应的导出模板字段。

[2022-12-13 16:35:32,558][dvadmin.utils.exception.CustomExceptionHandler():46] [ERROR] Traceback (most recent call last):
  File "D:\00-SoftWare\Python3.11\Lib\site-packages\rest_framework\views.py", line 506, in dispatch
    response = handler(request, *args, **kwargs)
               ^^^^^^^^^^^^^^^^^^^^^^^^^^^^^^^^^
  File "D:\00-SoftWare\Python3.11\Lib\contextlib.py", line 81, in inner
    return func(*args, **kwds)
           ^^^^^^^^^^^^^^^^^^^
  File "F:\django-vue-admin\backend\dvadmin\utils\import_export_mixin.py", line 163, in import_data
    serializer.is_valid(raise_exception=True)
  File "D:\00-SoftWare\Python3.11\Lib\site-packages\rest_framework\serializers.py", line 220, in is_valid
    self._validated_data = self.run_validation(self.initial_data)
                           ^^^^^^^^^^^^^^^^^^^^^^^^^^^^^^^^^^^^^^
  File "D:\00-SoftWare\Python3.11\Lib\site-packages\rest_framework\serializers.py", line 419, in run_validation
    value = self.to_internal_value(data)
            ^^^^^^^^^^^^^^^^^^^^^^^^^^^^
  File "D:\00-SoftWare\Python3.11\Lib\site-packages\rest_framework\serializers.py", line 472, in to_internal_value
    for field in fields:
  File "D:\00-SoftWare\Python3.11\Lib\site-packages\rest_framework\serializers.py", line 355, in _writable_fields
    for field in self.fields.values():
                 ^^^^^^^^^^^
  File "D:\00-SoftWare\Python3.11\Lib\site-packages\django_restql\mixins.py", line 424, in fields
    return self.allowed_fields
           ^^^^^^^^^^^^^^^^^^^
  File "D:\00-SoftWare\Python3.11\Lib\site-packages\django\utils\functional.py", line 48, in __get__
    res = instance.__dict__[self.name] = self.func(instance)
                                         ^^^^^^^^^^^^^^^^^^^
  File "D:\00-SoftWare\Python3.11\Lib\site-packages\django_restql\mixins.py", line 153, in allowed_fields
    fields = super().fields
             ^^^^^^^^^^^^^^
  File "D:\00-SoftWare\Python3.11\Lib\site-packages\django\utils\functional.py", line 48, in __get__
    res = instance.__dict__[self.name] = self.func(instance)
                                         ^^^^^^^^^^^^^^^^^^^
  File "D:\00-SoftWare\Python3.11\Lib\site-packages\rest_framework\serializers.py", line 349, in fields
    for key, value in self.get_fields().items():
                      ^^^^^^^^^^^^^^^^^
  File "D:\00-SoftWare\Python3.11\Lib\site-packages\rest_framework\serializers.py", line 1029, in get_fields
    field_names = self.get_field_names(declared_fields, info)
                  ^^^^^^^^^^^^^^^^^^^^^^^^^^^^^^^^^^^^^^^^^^^
  File "D:\00-SoftWare\Python3.11\Lib\site-packages\rest_framework\serializers.py", line 1152, in get_field_names
    assert field_name in fields, (
AssertionError: The field 'post' was included on serializer EmployeeProfileImportSerializer in the 'exclude' option, but does not match any model field.

[2022-12-15 11:38:36,341][dvadmin.utils.exception.CustomExceptionHandler():46] [ERROR] Traceback (most recent call last):
  File "D:\00-SoftWare\Python3.11\Lib\site-packages\rest_framework\views.py", line 506, in dispatch
    response = handler(request, *args, **kwargs)
               ^^^^^^^^^^^^^^^^^^^^^^^^^^^^^^^^^
  File "D:\00-SoftWare\Python3.11\Lib\contextlib.py", line 81, in inner
    return func(*args, **kwds)
           ^^^^^^^^^^^^^^^^^^^
  File "F:\django-vue-admin\backend\dvadmin\utils\import_export_mixin.py", line 163, in import_data
    serializer.is_valid(raise_exception=True)
  File "D:\00-SoftWare\Python3.11\Lib\site-packages\rest_framework\serializers.py", line 220, in is_valid
    self._validated_data = self.run_validation(self.initial_data)
                           ^^^^^^^^^^^^^^^^^^^^^^^^^^^^^^^^^^^^^^
  File "D:\00-SoftWare\Python3.11\Lib\site-packages\rest_framework\serializers.py", line 419, in run_validation
    value = self.to_internal_value(data)
            ^^^^^^^^^^^^^^^^^^^^^^^^^^^^
  File "D:\00-SoftWare\Python3.11\Lib\site-packages\rest_framework\serializers.py", line 472, in to_internal_value
    for field in fields:
  File "D:\00-SoftWare\Python3.11\Lib\site-packages\rest_framework\serializers.py", line 355, in _writable_fields
    for field in self.fields.values():
                 ^^^^^^^^^^^
  File "D:\00-SoftWare\Python3.11\Lib\site-packages\django_restql\mixins.py", line 424, in fields
    return self.allowed_fields
           ^^^^^^^^^^^^^^^^^^^
  File "D:\00-SoftWare\Python3.11\Lib\site-packages\django\utils\functional.py", line 48, in __get__
    res = instance.__dict__[self.name] = self.func(instance)
                                         ^^^^^^^^^^^^^^^^^^^
  File "D:\00-SoftWare\Python3.11\Lib\site-packages\django_restql\mixins.py", line 153, in allowed_fields
    fields = super().fields
             ^^^^^^^^^^^^^^
  File "D:\00-SoftWare\Python3.11\Lib\site-packages\django\utils\functional.py", line 48, in __get__
    res = instance.__dict__[self.name] = self.func(instance)
                                         ^^^^^^^^^^^^^^^^^^^
  File "D:\00-SoftWare\Python3.11\Lib\site-packages\rest_framework\serializers.py", line 349, in fields
    for key, value in self.get_fields().items():
                      ^^^^^^^^^^^^^^^^^
  File "D:\00-SoftWare\Python3.11\Lib\site-packages\rest_framework\serializers.py", line 1029, in get_fields
    field_names = self.get_field_names(declared_fields, info)
                  ^^^^^^^^^^^^^^^^^^^^^^^^^^^^^^^^^^^^^^^^^^^
  File "D:\00-SoftWare\Python3.11\Lib\site-packages\rest_framework\serializers.py", line 1101, in get_field_names
    assert not (fields is None and exclude is None), (
AssertionError: ("Creating a ModelSerializer without either the 'fields' attribute or the 'exclude' attribute has been deprecated since 3.3.0, and is now disallowed. Add an explicit fields = '__all__' to the EmployeeProfileImportSerializer serializer.",)

[2022-12-15 11:38:51,489][dvadmin.utils.exception.CustomExceptionHandler():46] [ERROR] Traceback (most recent call last):
  File "D:\00-SoftWare\Python3.11\Lib\site-packages\rest_framework\views.py", line 506, in dispatch
    response = handler(request, *args, **kwargs)
               ^^^^^^^^^^^^^^^^^^^^^^^^^^^^^^^^^
  File "D:\00-SoftWare\Python3.11\Lib\contextlib.py", line 81, in inner
    return func(*args, **kwds)
           ^^^^^^^^^^^^^^^^^^^
  File "F:\django-vue-admin\backend\dvadmin\utils\import_export_mixin.py", line 163, in import_data
    serializer.is_valid(raise_exception=True)
  File "D:\00-SoftWare\Python3.11\Lib\site-packages\rest_framework\serializers.py", line 220, in is_valid
    self._validated_data = self.run_validation(self.initial_data)
                           ^^^^^^^^^^^^^^^^^^^^^^^^^^^^^^^^^^^^^^
  File "D:\00-SoftWare\Python3.11\Lib\site-packages\rest_framework\serializers.py", line 419, in run_validation
    value = self.to_internal_value(data)
            ^^^^^^^^^^^^^^^^^^^^^^^^^^^^
  File "D:\00-SoftWare\Python3.11\Lib\site-packages\rest_framework\serializers.py", line 472, in to_internal_value
    for field in fields:
  File "D:\00-SoftWare\Python3.11\Lib\site-packages\rest_framework\serializers.py", line 355, in _writable_fields
    for field in self.fields.values():
                 ^^^^^^^^^^^
  File "D:\00-SoftWare\Python3.11\Lib\site-packages\django_restql\mixins.py", line 424, in fields
    return self.allowed_fields
           ^^^^^^^^^^^^^^^^^^^
  File "D:\00-SoftWare\Python3.11\Lib\site-packages\django\utils\functional.py", line 48, in __get__
    res = instance.__dict__[self.name] = self.func(instance)
                                         ^^^^^^^^^^^^^^^^^^^
  File "D:\00-SoftWare\Python3.11\Lib\site-packages\django_restql\mixins.py", line 153, in allowed_fields
    fields = super().fields
             ^^^^^^^^^^^^^^
  File "D:\00-SoftWare\Python3.11\Lib\site-packages\django\utils\functional.py", line 48, in __get__
    res = instance.__dict__[self.name] = self.func(instance)
                                         ^^^^^^^^^^^^^^^^^^^
  File "D:\00-SoftWare\Python3.11\Lib\site-packages\rest_framework\serializers.py", line 349, in fields
    for key, value in self.get_fields().items():
                      ^^^^^^^^^^^^^^^^^
  File "D:\00-SoftWare\Python3.11\Lib\site-packages\rest_framework\serializers.py", line 1029, in get_fields
    field_names = self.get_field_names(declared_fields, info)
                  ^^^^^^^^^^^^^^^^^^^^^^^^^^^^^^^^^^^^^^^^^^^
  File "D:\00-SoftWare\Python3.11\Lib\site-packages\rest_framework\serializers.py", line 1101, in get_field_names
    assert not (fields is None and exclude is None), (
AssertionError: ("Creating a ModelSerializer without either the 'fields' attribute or the 'exclude' attribute has been deprecated since 3.3.0, and is now disallowed. Add an explicit fields = '__all__' to the EmployeeProfileImportSerializer serializer.",)

[2022-12-15 11:39:09,438][dvadmin.utils.exception.CustomExceptionHandler():46] [ERROR] Traceback (most recent call last):
  File "D:\00-SoftWare\Python3.11\Lib\site-packages\rest_framework\views.py", line 506, in dispatch
    response = handler(request, *args, **kwargs)
               ^^^^^^^^^^^^^^^^^^^^^^^^^^^^^^^^^
  File "D:\00-SoftWare\Python3.11\Lib\contextlib.py", line 81, in inner
    return func(*args, **kwds)
           ^^^^^^^^^^^^^^^^^^^
  File "F:\django-vue-admin\backend\dvadmin\utils\import_export_mixin.py", line 163, in import_data
    serializer.is_valid(raise_exception=True)
  File "D:\00-SoftWare\Python3.11\Lib\site-packages\rest_framework\serializers.py", line 220, in is_valid
    self._validated_data = self.run_validation(self.initial_data)
                           ^^^^^^^^^^^^^^^^^^^^^^^^^^^^^^^^^^^^^^
  File "D:\00-SoftWare\Python3.11\Lib\site-packages\rest_framework\serializers.py", line 419, in run_validation
    value = self.to_internal_value(data)
            ^^^^^^^^^^^^^^^^^^^^^^^^^^^^
  File "D:\00-SoftWare\Python3.11\Lib\site-packages\rest_framework\serializers.py", line 472, in to_internal_value
    for field in fields:
  File "D:\00-SoftWare\Python3.11\Lib\site-packages\rest_framework\serializers.py", line 355, in _writable_fields
    for field in self.fields.values():
                 ^^^^^^^^^^^
  File "D:\00-SoftWare\Python3.11\Lib\site-packages\django_restql\mixins.py", line 424, in fields
    return self.allowed_fields
           ^^^^^^^^^^^^^^^^^^^
  File "D:\00-SoftWare\Python3.11\Lib\site-packages\django\utils\functional.py", line 48, in __get__
    res = instance.__dict__[self.name] = self.func(instance)
                                         ^^^^^^^^^^^^^^^^^^^
  File "D:\00-SoftWare\Python3.11\Lib\site-packages\django_restql\mixins.py", line 153, in allowed_fields
    fields = super().fields
             ^^^^^^^^^^^^^^
  File "D:\00-SoftWare\Python3.11\Lib\site-packages\django\utils\functional.py", line 48, in __get__
    res = instance.__dict__[self.name] = self.func(instance)
                                         ^^^^^^^^^^^^^^^^^^^
  File "D:\00-SoftWare\Python3.11\Lib\site-packages\rest_framework\serializers.py", line 349, in fields
    for key, value in self.get_fields().items():
                      ^^^^^^^^^^^^^^^^^
  File "D:\00-SoftWare\Python3.11\Lib\site-packages\rest_framework\serializers.py", line 1029, in get_fields
    field_names = self.get_field_names(declared_fields, info)
                  ^^^^^^^^^^^^^^^^^^^^^^^^^^^^^^^^^^^^^^^^^^^
  File "D:\00-SoftWare\Python3.11\Lib\site-packages\rest_framework\serializers.py", line 1101, in get_field_names
    assert not (fields is None and exclude is None), (
AssertionError: ("Creating a ModelSerializer without either the 'fields' attribute or the 'exclude' attribute has been deprecated since 3.3.0, and is now disallowed. Add an explicit fields = '__all__' to the EmployeeProfileImportSerializer serializer.",)

[2022-12-15 11:39:22,711][dvadmin.utils.exception.CustomExceptionHandler():46] [ERROR] Traceback (most recent call last):
  File "D:\00-SoftWare\Python3.11\Lib\site-packages\rest_framework\views.py", line 506, in dispatch
    response = handler(request, *args, **kwargs)
               ^^^^^^^^^^^^^^^^^^^^^^^^^^^^^^^^^
  File "D:\00-SoftWare\Python3.11\Lib\contextlib.py", line 81, in inner
    return func(*args, **kwds)
           ^^^^^^^^^^^^^^^^^^^
  File "F:\django-vue-admin\backend\dvadmin\utils\import_export_mixin.py", line 163, in import_data
    serializer.is_valid(raise_exception=True)
  File "D:\00-SoftWare\Python3.11\Lib\site-packages\rest_framework\serializers.py", line 220, in is_valid
    self._validated_data = self.run_validation(self.initial_data)
                           ^^^^^^^^^^^^^^^^^^^^^^^^^^^^^^^^^^^^^^
  File "D:\00-SoftWare\Python3.11\Lib\site-packages\rest_framework\serializers.py", line 419, in run_validation
    value = self.to_internal_value(data)
            ^^^^^^^^^^^^^^^^^^^^^^^^^^^^
  File "D:\00-SoftWare\Python3.11\Lib\site-packages\rest_framework\serializers.py", line 472, in to_internal_value
    for field in fields:
  File "D:\00-SoftWare\Python3.11\Lib\site-packages\rest_framework\serializers.py", line 355, in _writable_fields
    for field in self.fields.values():
                 ^^^^^^^^^^^
  File "D:\00-SoftWare\Python3.11\Lib\site-packages\django_restql\mixins.py", line 424, in fields
    return self.allowed_fields
           ^^^^^^^^^^^^^^^^^^^
  File "D:\00-SoftWare\Python3.11\Lib\site-packages\django\utils\functional.py", line 48, in __get__
    res = instance.__dict__[self.name] = self.func(instance)
                                         ^^^^^^^^^^^^^^^^^^^
  File "D:\00-SoftWare\Python3.11\Lib\site-packages\django_restql\mixins.py", line 153, in allowed_fields
    fields = super().fields
             ^^^^^^^^^^^^^^
  File "D:\00-SoftWare\Python3.11\Lib\site-packages\django\utils\functional.py", line 48, in __get__
    res = instance.__dict__[self.name] = self.func(instance)
                                         ^^^^^^^^^^^^^^^^^^^
  File "D:\00-SoftWare\Python3.11\Lib\site-packages\rest_framework\serializers.py", line 349, in fields
    for key, value in self.get_fields().items():
                      ^^^^^^^^^^^^^^^^^
  File "D:\00-SoftWare\Python3.11\Lib\site-packages\rest_framework\serializers.py", line 1029, in get_fields
    field_names = self.get_field_names(declared_fields, info)
                  ^^^^^^^^^^^^^^^^^^^^^^^^^^^^^^^^^^^^^^^^^^^
  File "D:\00-SoftWare\Python3.11\Lib\site-packages\rest_framework\serializers.py", line 1101, in get_field_names
    assert not (fields is None and exclude is None), (
AssertionError: ("Creating a ModelSerializer without either the 'fields' attribute or the 'exclude' attribute has been deprecated since 3.3.0, and is now disallowed. Add an explicit fields = '__all__' to the EmployeeProfileImportSerializer serializer.",)

[2022-12-15 13:23:26,635][django.request.log_response():224] [ERROR] Internal Server Error: /api/system/employee/exportWord/
Traceback (most recent call last):
  File "D:\00-SoftWare\Python3.11\Lib\site-packages\asgiref\sync.py", line 472, in thread_handler
    raise exc_info[1]
  File "D:\00-SoftWare\Python3.11\Lib\site-packages\django\core\handlers\exception.py", line 38, in inner
    response = await get_response(request)
               ^^^^^^^^^^^^^^^^^^^^^^^^^^^
  File "D:\00-SoftWare\Python3.11\Lib\site-packages\asgiref\sync.py", line 472, in thread_handler
    raise exc_info[1]
  File "D:\00-SoftWare\Python3.11\Lib\site-packages\django\core\handlers\base.py", line 233, in _get_response_async
    response = await wrapped_callback(request, *callback_args, **callback_kwargs)
               ^^^^^^^^^^^^^^^^^^^^^^^^^^^^^^^^^^^^^^^^^^^^^^^^^^^^^^^^^^^^^^^^^^
  File "D:\00-SoftWare\Python3.11\Lib\site-packages\asgiref\sync.py", line 435, in __call__
    ret = await asyncio.wait_for(future, timeout=None)
          ^^^^^^^^^^^^^^^^^^^^^^^^^^^^^^^^^^^^^^^^^^^^
  File "D:\00-SoftWare\Python3.11\Lib\asyncio\tasks.py", line 442, in wait_for
    return await fut
           ^^^^^^^^^
  File "D:\00-SoftWare\Python3.11\Lib\site-packages\asgiref\current_thread_executor.py", line 22, in run
    result = self.fn(*self.args, **self.kwargs)
             ^^^^^^^^^^^^^^^^^^^^^^^^^^^^^^^^^^
  File "D:\00-SoftWare\Python3.11\Lib\site-packages\asgiref\sync.py", line 476, in thread_handler
    return func(*args, **kwargs)
           ^^^^^^^^^^^^^^^^^^^^^
  File "D:\00-SoftWare\Python3.11\Lib\site-packages\django\views\decorators\csrf.py", line 54, in wrapped_view
    return view_func(*args, **kwargs)
           ^^^^^^^^^^^^^^^^^^^^^^^^^^
  File "D:\00-SoftWare\Python3.11\Lib\site-packages\rest_framework\viewsets.py", line 117, in view
    handler = getattr(self, action)
              ^^^^^^^^^^^^^^^^^^^^^
AttributeError: 'EmployeeViewSet' object has no attribute 'export_employee_info'
[2022-12-15 13:23:26,643][django.channels.server.log_action():160] [ERROR] HTTP POST /api/system/employee/exportWord/ 500 [0.12, 127.0.0.1:5234]
[2022-12-15 13:23:39,811][django.request.log_response():224] [ERROR] Internal Server Error: /api/system/employee/exportWord/
Traceback (most recent call last):
  File "D:\00-SoftWare\Python3.11\Lib\site-packages\asgiref\sync.py", line 472, in thread_handler
    raise exc_info[1]
  File "D:\00-SoftWare\Python3.11\Lib\site-packages\django\core\handlers\exception.py", line 38, in inner
    response = await get_response(request)
               ^^^^^^^^^^^^^^^^^^^^^^^^^^^
  File "D:\00-SoftWare\Python3.11\Lib\site-packages\asgiref\sync.py", line 472, in thread_handler
    raise exc_info[1]
  File "D:\00-SoftWare\Python3.11\Lib\site-packages\django\core\handlers\base.py", line 233, in _get_response_async
    response = await wrapped_callback(request, *callback_args, **callback_kwargs)
               ^^^^^^^^^^^^^^^^^^^^^^^^^^^^^^^^^^^^^^^^^^^^^^^^^^^^^^^^^^^^^^^^^^
  File "D:\00-SoftWare\Python3.11\Lib\site-packages\asgiref\sync.py", line 435, in __call__
    ret = await asyncio.wait_for(future, timeout=None)
          ^^^^^^^^^^^^^^^^^^^^^^^^^^^^^^^^^^^^^^^^^^^^
  File "D:\00-SoftWare\Python3.11\Lib\asyncio\tasks.py", line 442, in wait_for
    return await fut
           ^^^^^^^^^
  File "D:\00-SoftWare\Python3.11\Lib\site-packages\asgiref\current_thread_executor.py", line 22, in run
    result = self.fn(*self.args, **self.kwargs)
             ^^^^^^^^^^^^^^^^^^^^^^^^^^^^^^^^^^
  File "D:\00-SoftWare\Python3.11\Lib\site-packages\asgiref\sync.py", line 476, in thread_handler
    return func(*args, **kwargs)
           ^^^^^^^^^^^^^^^^^^^^^
  File "D:\00-SoftWare\Python3.11\Lib\site-packages\django\views\decorators\csrf.py", line 54, in wrapped_view
    return view_func(*args, **kwargs)
           ^^^^^^^^^^^^^^^^^^^^^^^^^^
  File "D:\00-SoftWare\Python3.11\Lib\site-packages\rest_framework\viewsets.py", line 117, in view
    handler = getattr(self, action)
              ^^^^^^^^^^^^^^^^^^^^^
AttributeError: 'EmployeeViewSet' object has no attribute 'export_employee_info'
[2022-12-15 13:23:39,817][django.channels.server.log_action():160] [ERROR] HTTP POST /api/system/employee/exportWord/ 500 [0.06, 127.0.0.1:5234]
[2022-12-15 13:23:53,097][django.request.log_response():224] [ERROR] Internal Server Error: /api/system/employee/exportWord/
Traceback (most recent call last):
  File "D:\00-SoftWare\Python3.11\Lib\site-packages\asgiref\sync.py", line 472, in thread_handler
    raise exc_info[1]
  File "D:\00-SoftWare\Python3.11\Lib\site-packages\django\core\handlers\exception.py", line 38, in inner
    response = await get_response(request)
               ^^^^^^^^^^^^^^^^^^^^^^^^^^^
  File "D:\00-SoftWare\Python3.11\Lib\site-packages\asgiref\sync.py", line 472, in thread_handler
    raise exc_info[1]
  File "D:\00-SoftWare\Python3.11\Lib\site-packages\django\core\handlers\base.py", line 233, in _get_response_async
    response = await wrapped_callback(request, *callback_args, **callback_kwargs)
               ^^^^^^^^^^^^^^^^^^^^^^^^^^^^^^^^^^^^^^^^^^^^^^^^^^^^^^^^^^^^^^^^^^
  File "D:\00-SoftWare\Python3.11\Lib\site-packages\asgiref\sync.py", line 435, in __call__
    ret = await asyncio.wait_for(future, timeout=None)
          ^^^^^^^^^^^^^^^^^^^^^^^^^^^^^^^^^^^^^^^^^^^^
  File "D:\00-SoftWare\Python3.11\Lib\asyncio\tasks.py", line 442, in wait_for
    return await fut
           ^^^^^^^^^
  File "D:\00-SoftWare\Python3.11\Lib\site-packages\asgiref\current_thread_executor.py", line 22, in run
    result = self.fn(*self.args, **self.kwargs)
             ^^^^^^^^^^^^^^^^^^^^^^^^^^^^^^^^^^
  File "D:\00-SoftWare\Python3.11\Lib\site-packages\asgiref\sync.py", line 476, in thread_handler
    return func(*args, **kwargs)
           ^^^^^^^^^^^^^^^^^^^^^
  File "D:\00-SoftWare\Python3.11\Lib\site-packages\django\views\decorators\csrf.py", line 54, in wrapped_view
    return view_func(*args, **kwargs)
           ^^^^^^^^^^^^^^^^^^^^^^^^^^
  File "D:\00-SoftWare\Python3.11\Lib\site-packages\rest_framework\viewsets.py", line 117, in view
    handler = getattr(self, action)
              ^^^^^^^^^^^^^^^^^^^^^
AttributeError: 'EmployeeViewSet' object has no attribute 'export_employee_info'
[2022-12-15 13:23:53,105][django.channels.server.log_action():160] [ERROR] HTTP POST /api/system/employee/exportWord/ 500 [0.11, 127.0.0.1:5267]
[2022-12-15 13:46:44,399][dvadmin.utils.exception.CustomExceptionHandler():46] [ERROR] Traceback (most recent call last):
  File "D:\00-SoftWare\Python3.11\Lib\site-packages\rest_framework\views.py", line 506, in dispatch
    response = handler(request, *args, **kwargs)
               ^^^^^^^^^^^^^^^^^^^^^^^^^^^^^^^^^
TypeError: EmployeeViewSet.export_employee_info() got an unexpected keyword argument 'pk'

[2022-12-15 16:36:14,147][dvadmin.utils.exception.CustomExceptionHandler():46] [ERROR] Traceback (most recent call last):
  File "D:\00-SoftWare\Python3.11\Lib\site-packages\rest_framework\views.py", line 506, in dispatch
    response = handler(request, *args, **kwargs)
               ^^^^^^^^^^^^^^^^^^^^^^^^^^^^^^^^^
  File "F:\django-vue-admin\backend\dvadmin\system\views\employee.py", line 115, in export_employee_info
    doc.render(context)  # 执行替换
    ^^^^^^^^^^^^^^^^^^^
  File "D:\00-SoftWare\Python3.11\Lib\site-packages\docxtpl\template.py", line 334, in render
    self.render_init()
  File "D:\00-SoftWare\Python3.11\Lib\site-packages\docxtpl\template.py", line 52, in render_init
    self.init_docx()
  File "D:\00-SoftWare\Python3.11\Lib\site-packages\docxtpl\template.py", line 48, in init_docx
    self.docx = Document(self.template_file)
                ^^^^^^^^^^^^^^^^^^^^^^^^^^^^
  File "D:\00-SoftWare\Python3.11\Lib\site-packages\docx\api.py", line 25, in Document
    document_part = Package.open(docx).main_document_part
                    ^^^^^^^^^^^^^^^^^^
  File "D:\00-SoftWare\Python3.11\Lib\site-packages\docx\opc\package.py", line 128, in open
    pkg_reader = PackageReader.from_file(pkg_file)
                 ^^^^^^^^^^^^^^^^^^^^^^^^^^^^^^^^^
  File "D:\00-SoftWare\Python3.11\Lib\site-packages\docx\opc\pkgreader.py", line 32, in from_file
    phys_reader = PhysPkgReader(pkg_file)
                  ^^^^^^^^^^^^^^^^^^^^^^^
  File "D:\00-SoftWare\Python3.11\Lib\site-packages\docx\opc\phys_pkg.py", line 30, in __new__
    raise PackageNotFoundError(
docx.opc.exceptions.PackageNotFoundError: Package not found at 'employee_info_template.docx'

[2022-12-15 16:36:52,546][dvadmin.utils.exception.CustomExceptionHandler():46] [ERROR] Traceback (most recent call last):
  File "D:\00-SoftWare\Python3.11\Lib\site-packages\rest_framework\views.py", line 506, in dispatch
    response = handler(request, *args, **kwargs)
               ^^^^^^^^^^^^^^^^^^^^^^^^^^^^^^^^^
  File "F:\django-vue-admin\backend\dvadmin\system\views\employee.py", line 114, in export_employee_info
    doc.render(context)  # 执行替换
    ^^^^^^^^^^^^^^^^^^^
  File "D:\00-SoftWare\Python3.11\Lib\site-packages\docxtpl\template.py", line 334, in render
    self.render_init()
  File "D:\00-SoftWare\Python3.11\Lib\site-packages\docxtpl\template.py", line 52, in render_init
    self.init_docx()
  File "D:\00-SoftWare\Python3.11\Lib\site-packages\docxtpl\template.py", line 48, in init_docx
    self.docx = Document(self.template_file)
                ^^^^^^^^^^^^^^^^^^^^^^^^^^^^
  File "D:\00-SoftWare\Python3.11\Lib\site-packages\docx\api.py", line 25, in Document
    document_part = Package.open(docx).main_document_part
                    ^^^^^^^^^^^^^^^^^^
  File "D:\00-SoftWare\Python3.11\Lib\site-packages\docx\opc\package.py", line 128, in open
    pkg_reader = PackageReader.from_file(pkg_file)
                 ^^^^^^^^^^^^^^^^^^^^^^^^^^^^^^^^^
  File "D:\00-SoftWare\Python3.11\Lib\site-packages\docx\opc\pkgreader.py", line 32, in from_file
    phys_reader = PhysPkgReader(pkg_file)
                  ^^^^^^^^^^^^^^^^^^^^^^^
  File "D:\00-SoftWare\Python3.11\Lib\site-packages\docx\opc\phys_pkg.py", line 30, in __new__
    raise PackageNotFoundError(
docx.opc.exceptions.PackageNotFoundError: Package not found at 'employee_info_template.docx'

[2022-12-15 16:48:16,632][dvadmin.utils.exception.CustomExceptionHandler():46] [ERROR] Traceback (most recent call last):
  File "D:\00-SoftWare\Python3.11\Lib\site-packages\rest_framework\views.py", line 506, in dispatch
    response = handler(request, *args, **kwargs)
               ^^^^^^^^^^^^^^^^^^^^^^^^^^^^^^^^^
  File "F:\django-vue-admin\backend\dvadmin\system\views\employee.py", line 114, in export_employee_info
    doc.render(context)  # 执行替换
    ^^^^^^^^^^^^^^^^^^^
  File "D:\00-SoftWare\Python3.11\Lib\site-packages\docxtpl\template.py", line 334, in render
    self.render_init()
  File "D:\00-SoftWare\Python3.11\Lib\site-packages\docxtpl\template.py", line 52, in render_init
    self.init_docx()
  File "D:\00-SoftWare\Python3.11\Lib\site-packages\docxtpl\template.py", line 48, in init_docx
    self.docx = Document(self.template_file)
                ^^^^^^^^^^^^^^^^^^^^^^^^^^^^
  File "D:\00-SoftWare\Python3.11\Lib\site-packages\docx\api.py", line 25, in Document
    document_part = Package.open(docx).main_document_part
                    ^^^^^^^^^^^^^^^^^^
  File "D:\00-SoftWare\Python3.11\Lib\site-packages\docx\opc\package.py", line 128, in open
    pkg_reader = PackageReader.from_file(pkg_file)
                 ^^^^^^^^^^^^^^^^^^^^^^^^^^^^^^^^^
  File "D:\00-SoftWare\Python3.11\Lib\site-packages\docx\opc\pkgreader.py", line 32, in from_file
    phys_reader = PhysPkgReader(pkg_file)
                  ^^^^^^^^^^^^^^^^^^^^^^^
  File "D:\00-SoftWare\Python3.11\Lib\site-packages\docx\opc\phys_pkg.py", line 30, in __new__
    raise PackageNotFoundError(
docx.opc.exceptions.PackageNotFoundError: Package not found at 'static\file_template\employee_info_template.docx'

[2022-12-15 16:49:21,562][dvadmin.utils.exception.CustomExceptionHandler():46] [ERROR] Traceback (most recent call last):
  File "D:\00-SoftWare\Python3.11\Lib\site-packages\rest_framework\views.py", line 506, in dispatch
    response = handler(request, *args, **kwargs)
               ^^^^^^^^^^^^^^^^^^^^^^^^^^^^^^^^^
  File "F:\django-vue-admin\backend\dvadmin\system\views\employee.py", line 114, in export_employee_info
    doc.render(context)  # 执行替换
    ^^^^^^^^^^^^^^^^^^^
  File "D:\00-SoftWare\Python3.11\Lib\site-packages\docxtpl\template.py", line 334, in render
    self.render_init()
  File "D:\00-SoftWare\Python3.11\Lib\site-packages\docxtpl\template.py", line 52, in render_init
    self.init_docx()
  File "D:\00-SoftWare\Python3.11\Lib\site-packages\docxtpl\template.py", line 48, in init_docx
    self.docx = Document(self.template_file)
                ^^^^^^^^^^^^^^^^^^^^^^^^^^^^
  File "D:\00-SoftWare\Python3.11\Lib\site-packages\docx\api.py", line 25, in Document
    document_part = Package.open(docx).main_document_part
                    ^^^^^^^^^^^^^^^^^^
  File "D:\00-SoftWare\Python3.11\Lib\site-packages\docx\opc\package.py", line 128, in open
    pkg_reader = PackageReader.from_file(pkg_file)
                 ^^^^^^^^^^^^^^^^^^^^^^^^^^^^^^^^^
  File "D:\00-SoftWare\Python3.11\Lib\site-packages\docx\opc\pkgreader.py", line 32, in from_file
    phys_reader = PhysPkgReader(pkg_file)
                  ^^^^^^^^^^^^^^^^^^^^^^^
  File "D:\00-SoftWare\Python3.11\Lib\site-packages\docx\opc\phys_pkg.py", line 30, in __new__
    raise PackageNotFoundError(
docx.opc.exceptions.PackageNotFoundError: Package not found at '\static\file_template\employee_info_template.docx'

[2022-12-15 17:02:56,457][dvadmin.utils.exception.CustomExceptionHandler():46] [ERROR] Traceback (most recent call last):
  File "D:\00-SoftWare\Python3.11\Lib\site-packages\rest_framework\views.py", line 506, in dispatch
    response = handler(request, *args, **kwargs)
               ^^^^^^^^^^^^^^^^^^^^^^^^^^^^^^^^^
  File "F:\django-vue-admin\backend\dvadmin\system\views\employee.py", line 114, in export_employee_info
    doc.render(context)  # 执行替换
    ^^^^^^^^^^^^^^^^^^^
  File "D:\00-SoftWare\Python3.11\Lib\site-packages\docxtpl\template.py", line 334, in render
    self.render_init()
  File "D:\00-SoftWare\Python3.11\Lib\site-packages\docxtpl\template.py", line 52, in render_init
    self.init_docx()
  File "D:\00-SoftWare\Python3.11\Lib\site-packages\docxtpl\template.py", line 48, in init_docx
    self.docx = Document(self.template_file)
                ^^^^^^^^^^^^^^^^^^^^^^^^^^^^
  File "D:\00-SoftWare\Python3.11\Lib\site-packages\docx\api.py", line 25, in Document
    document_part = Package.open(docx).main_document_part
                    ^^^^^^^^^^^^^^^^^^
  File "D:\00-SoftWare\Python3.11\Lib\site-packages\docx\opc\package.py", line 128, in open
    pkg_reader = PackageReader.from_file(pkg_file)
                 ^^^^^^^^^^^^^^^^^^^^^^^^^^^^^^^^^
  File "D:\00-SoftWare\Python3.11\Lib\site-packages\docx\opc\pkgreader.py", line 32, in from_file
    phys_reader = PhysPkgReader(pkg_file)
                  ^^^^^^^^^^^^^^^^^^^^^^^
  File "D:\00-SoftWare\Python3.11\Lib\site-packages\docx\opc\phys_pkg.py", line 30, in __new__
    raise PackageNotFoundError(
docx.opc.exceptions.PackageNotFoundError: Package not found at 'employee_info_template.docx'

[2022-12-15 17:04:19,744][dvadmin.utils.exception.CustomExceptionHandler():46] [ERROR] Traceback (most recent call last):
  File "D:\00-SoftWare\Python3.11\Lib\site-packages\rest_framework\views.py", line 506, in dispatch
    response = handler(request, *args, **kwargs)
               ^^^^^^^^^^^^^^^^^^^^^^^^^^^^^^^^^
  File "F:\django-vue-admin\backend\dvadmin\system\views\employee.py", line 114, in export_employee_info
    doc.render(context)  # 执行替换
    ^^^^^^^^^^^^^^^^^^^
  File "D:\00-SoftWare\Python3.11\Lib\site-packages\docxtpl\template.py", line 334, in render
    self.render_init()
  File "D:\00-SoftWare\Python3.11\Lib\site-packages\docxtpl\template.py", line 52, in render_init
    self.init_docx()
  File "D:\00-SoftWare\Python3.11\Lib\site-packages\docxtpl\template.py", line 48, in init_docx
    self.docx = Document(self.template_file)
                ^^^^^^^^^^^^^^^^^^^^^^^^^^^^
  File "D:\00-SoftWare\Python3.11\Lib\site-packages\docx\api.py", line 25, in Document
    document_part = Package.open(docx).main_document_part
                    ^^^^^^^^^^^^^^^^^^
  File "D:\00-SoftWare\Python3.11\Lib\site-packages\docx\opc\package.py", line 128, in open
    pkg_reader = PackageReader.from_file(pkg_file)
                 ^^^^^^^^^^^^^^^^^^^^^^^^^^^^^^^^^
  File "D:\00-SoftWare\Python3.11\Lib\site-packages\docx\opc\pkgreader.py", line 32, in from_file
    phys_reader = PhysPkgReader(pkg_file)
                  ^^^^^^^^^^^^^^^^^^^^^^^
  File "D:\00-SoftWare\Python3.11\Lib\site-packages\docx\opc\phys_pkg.py", line 30, in __new__
    raise PackageNotFoundError(
docx.opc.exceptions.PackageNotFoundError: Package not found at '\\static\\employee_info_template.docx'

[2022-12-15 17:04:31,938][dvadmin.utils.exception.CustomExceptionHandler():46] [ERROR] Traceback (most recent call last):
  File "D:\00-SoftWare\Python3.11\Lib\site-packages\rest_framework\views.py", line 506, in dispatch
    response = handler(request, *args, **kwargs)
               ^^^^^^^^^^^^^^^^^^^^^^^^^^^^^^^^^
  File "F:\django-vue-admin\backend\dvadmin\system\views\employee.py", line 114, in export_employee_info
    doc.render(context)  # 执行替换
    ^^^^^^^^^^^^^^^^^^^
  File "D:\00-SoftWare\Python3.11\Lib\site-packages\docxtpl\template.py", line 334, in render
    self.render_init()
  File "D:\00-SoftWare\Python3.11\Lib\site-packages\docxtpl\template.py", line 52, in render_init
    self.init_docx()
  File "D:\00-SoftWare\Python3.11\Lib\site-packages\docxtpl\template.py", line 48, in init_docx
    self.docx = Document(self.template_file)
                ^^^^^^^^^^^^^^^^^^^^^^^^^^^^
  File "D:\00-SoftWare\Python3.11\Lib\site-packages\docx\api.py", line 25, in Document
    document_part = Package.open(docx).main_document_part
                    ^^^^^^^^^^^^^^^^^^
  File "D:\00-SoftWare\Python3.11\Lib\site-packages\docx\opc\package.py", line 128, in open
    pkg_reader = PackageReader.from_file(pkg_file)
                 ^^^^^^^^^^^^^^^^^^^^^^^^^^^^^^^^^
  File "D:\00-SoftWare\Python3.11\Lib\site-packages\docx\opc\pkgreader.py", line 32, in from_file
    phys_reader = PhysPkgReader(pkg_file)
                  ^^^^^^^^^^^^^^^^^^^^^^^
  File "D:\00-SoftWare\Python3.11\Lib\site-packages\docx\opc\phys_pkg.py", line 30, in __new__
    raise PackageNotFoundError(
docx.opc.exceptions.PackageNotFoundError: Package not found at '\\static\\employee_info_template.docx'

[2022-12-15 17:05:51,649][dvadmin.utils.exception.CustomExceptionHandler():46] [ERROR] Traceback (most recent call last):
  File "D:\00-SoftWare\Python3.11\Lib\site-packages\rest_framework\views.py", line 506, in dispatch
    response = handler(request, *args, **kwargs)
               ^^^^^^^^^^^^^^^^^^^^^^^^^^^^^^^^^
  File "F:\django-vue-admin\backend\dvadmin\system\views\employee.py", line 114, in export_employee_info
    doc.render(context)  # 执行替换
    ^^^^^^^^^^^^^^^^^^^
  File "D:\00-SoftWare\Python3.11\Lib\site-packages\docxtpl\template.py", line 334, in render
    self.render_init()
  File "D:\00-SoftWare\Python3.11\Lib\site-packages\docxtpl\template.py", line 52, in render_init
    self.init_docx()
  File "D:\00-SoftWare\Python3.11\Lib\site-packages\docxtpl\template.py", line 48, in init_docx
    self.docx = Document(self.template_file)
                ^^^^^^^^^^^^^^^^^^^^^^^^^^^^
  File "D:\00-SoftWare\Python3.11\Lib\site-packages\docx\api.py", line 25, in Document
    document_part = Package.open(docx).main_document_part
                    ^^^^^^^^^^^^^^^^^^
  File "D:\00-SoftWare\Python3.11\Lib\site-packages\docx\opc\package.py", line 128, in open
    pkg_reader = PackageReader.from_file(pkg_file)
                 ^^^^^^^^^^^^^^^^^^^^^^^^^^^^^^^^^
  File "D:\00-SoftWare\Python3.11\Lib\site-packages\docx\opc\pkgreader.py", line 32, in from_file
    phys_reader = PhysPkgReader(pkg_file)
                  ^^^^^^^^^^^^^^^^^^^^^^^
  File "D:\00-SoftWare\Python3.11\Lib\site-packages\docx\opc\phys_pkg.py", line 30, in __new__
    raise PackageNotFoundError(
docx.opc.exceptions.PackageNotFoundError: Package not found at 'static\file_template\employee_info_template.docx'

[2022-12-16 12:13:20,600][dvadmin.utils.exception.CustomExceptionHandler():46] [ERROR] Traceback (most recent call last):
  File "D:\00-SoftWare\Python3.11\Lib\site-packages\rest_framework\views.py", line 506, in dispatch
    response = handler(request, *args, **kwargs)
               ^^^^^^^^^^^^^^^^^^^^^^^^^^^^^^^^^
  File "F:\django-vue-admin\backend\dvadmin\system\views\employee.py", line 118, in export_employee_info
    response["content-disposition"] = f'attachment;filename={quote(str(data["name"] + ".xlsx"))}'
                                                                       ~~~~^^^^^^^^
TypeError: list indices must be integers or slices, not str

[2022-12-16 12:14:55,007][dvadmin.utils.exception.CustomExceptionHandler():46] [ERROR] Traceback (most recent call last):
  File "D:\00-SoftWare\Python3.11\Lib\site-packages\rest_framework\views.py", line 506, in dispatch
    response = handler(request, *args, **kwargs)
               ^^^^^^^^^^^^^^^^^^^^^^^^^^^^^^^^^
  File "F:\django-vue-admin\backend\dvadmin\system\views\employee.py", line 118, in export_employee_info
    response["content-disposition"] = f'attachment;filename={quote(str(data["name"] + ".xlsx"))}'
                                                                       ~~~~^^^^^^^^
TypeError: list indices must be integers or slices, not str

[2022-12-16 12:33:27,296][dvadmin.utils.exception.CustomExceptionHandler():46] [ERROR] Traceback (most recent call last):
  File "D:\00-SoftWare\Python3.11\Lib\site-packages\rest_framework\views.py", line 506, in dispatch
    response = handler(request, *args, **kwargs)
               ^^^^^^^^^^^^^^^^^^^^^^^^^^^^^^^^^
  File "F:\django-vue-admin\backend\dvadmin\system\views\employee.py", line 122, in export_employee_info
    doc.save("E:\\文档\\"+data['name']+".docx")  # 保存新的文档
                        ~~~~^^^^^^^^
TypeError: list indices must be integers or slices, not str

[2022-12-16 12:34:00,154][dvadmin.utils.exception.CustomExceptionHandler():46] [ERROR] Traceback (most recent call last):
  File "D:\00-SoftWare\Python3.11\Lib\site-packages\rest_framework\views.py", line 506, in dispatch
    response = handler(request, *args, **kwargs)
               ^^^^^^^^^^^^^^^^^^^^^^^^^^^^^^^^^
  File "F:\django-vue-admin\backend\dvadmin\system\views\employee.py", line 122, in export_employee_info
    doc.save("E:\\文档\\"+data['name']+".docx")  # 保存新的文档
                        ~~~~^^^^^^^^
TypeError: list indices must be integers or slices, not str

[2022-12-16 13:02:22,134][django.request.log_response():224] [ERROR] Internal Server Error: /api/system/employee/export_employee_info/
Traceback (most recent call last):
  File "D:\00-SoftWare\Python3.11\Lib\site-packages\asgiref\sync.py", line 472, in thread_handler
    raise exc_info[1]
  File "D:\00-SoftWare\Python3.11\Lib\site-packages\django\core\handlers\exception.py", line 38, in inner
    response = await get_response(request)
               ^^^^^^^^^^^^^^^^^^^^^^^^^^^
  File "D:\00-SoftWare\Python3.11\Lib\site-packages\asgiref\sync.py", line 472, in thread_handler
    raise exc_info[1]
  File "D:\00-SoftWare\Python3.11\Lib\site-packages\django\core\handlers\base.py", line 233, in _get_response_async
    response = await wrapped_callback(request, *callback_args, **callback_kwargs)
               ^^^^^^^^^^^^^^^^^^^^^^^^^^^^^^^^^^^^^^^^^^^^^^^^^^^^^^^^^^^^^^^^^^
  File "D:\00-SoftWare\Python3.11\Lib\site-packages\asgiref\sync.py", line 435, in __call__
    ret = await asyncio.wait_for(future, timeout=None)
          ^^^^^^^^^^^^^^^^^^^^^^^^^^^^^^^^^^^^^^^^^^^^
  File "D:\00-SoftWare\Python3.11\Lib\asyncio\tasks.py", line 442, in wait_for
    return await fut
           ^^^^^^^^^
  File "D:\00-SoftWare\Python3.11\Lib\site-packages\asgiref\current_thread_executor.py", line 22, in run
    result = self.fn(*self.args, **self.kwargs)
             ^^^^^^^^^^^^^^^^^^^^^^^^^^^^^^^^^^
  File "D:\00-SoftWare\Python3.11\Lib\site-packages\asgiref\sync.py", line 476, in thread_handler
    return func(*args, **kwargs)
           ^^^^^^^^^^^^^^^^^^^^^
  File "D:\00-SoftWare\Python3.11\Lib\site-packages\django\views\decorators\csrf.py", line 54, in wrapped_view
    return view_func(*args, **kwargs)
           ^^^^^^^^^^^^^^^^^^^^^^^^^^
  File "D:\00-SoftWare\Python3.11\Lib\site-packages\rest_framework\viewsets.py", line 125, in view
    return self.dispatch(request, *args, **kwargs)
           ^^^^^^^^^^^^^^^^^^^^^^^^^^^^^^^^^^^^^^^
  File "D:\00-SoftWare\Python3.11\Lib\site-packages\rest_framework\views.py", line 511, in dispatch
    self.response = self.finalize_response(request, response, *args, **kwargs)
                    ^^^^^^^^^^^^^^^^^^^^^^^^^^^^^^^^^^^^^^^^^^^^^^^^^^^^^^^^^^
  File "D:\00-SoftWare\Python3.11\Lib\site-packages\rest_framework\views.py", line 423, in finalize_response
    assert isinstance(response, HttpResponseBase), (
AssertionError: Expected a `Response`, `HttpResponse` or `HttpStreamingResponse` to be returned from the view, but received a `<class 'list'>`
[2022-12-16 13:02:22,150][django.channels.server.log_action():160] [ERROR] HTTP POST /api/system/employee/export_employee_info/ 500 [0.22, 127.0.0.1:13382]
[2022-12-16 13:03:35,125][django.request.log_response():224] [ERROR] Internal Server Error: /api/system/employee/export_employee_info/
Traceback (most recent call last):
  File "D:\00-SoftWare\Python3.11\Lib\site-packages\asgiref\sync.py", line 472, in thread_handler
    raise exc_info[1]
  File "D:\00-SoftWare\Python3.11\Lib\site-packages\django\core\handlers\exception.py", line 38, in inner
    response = await get_response(request)
               ^^^^^^^^^^^^^^^^^^^^^^^^^^^
  File "D:\00-SoftWare\Python3.11\Lib\site-packages\asgiref\sync.py", line 472, in thread_handler
    raise exc_info[1]
  File "D:\00-SoftWare\Python3.11\Lib\site-packages\django\core\handlers\base.py", line 233, in _get_response_async
    response = await wrapped_callback(request, *callback_args, **callback_kwargs)
               ^^^^^^^^^^^^^^^^^^^^^^^^^^^^^^^^^^^^^^^^^^^^^^^^^^^^^^^^^^^^^^^^^^
  File "D:\00-SoftWare\Python3.11\Lib\site-packages\asgiref\sync.py", line 435, in __call__
    ret = await asyncio.wait_for(future, timeout=None)
          ^^^^^^^^^^^^^^^^^^^^^^^^^^^^^^^^^^^^^^^^^^^^
  File "D:\00-SoftWare\Python3.11\Lib\asyncio\tasks.py", line 442, in wait_for
    return await fut
           ^^^^^^^^^
  File "D:\00-SoftWare\Python3.11\Lib\site-packages\asgiref\current_thread_executor.py", line 22, in run
    result = self.fn(*self.args, **self.kwargs)
             ^^^^^^^^^^^^^^^^^^^^^^^^^^^^^^^^^^
  File "D:\00-SoftWare\Python3.11\Lib\site-packages\asgiref\sync.py", line 476, in thread_handler
    return func(*args, **kwargs)
           ^^^^^^^^^^^^^^^^^^^^^
  File "D:\00-SoftWare\Python3.11\Lib\site-packages\django\views\decorators\csrf.py", line 54, in wrapped_view
    return view_func(*args, **kwargs)
           ^^^^^^^^^^^^^^^^^^^^^^^^^^
  File "D:\00-SoftWare\Python3.11\Lib\site-packages\rest_framework\viewsets.py", line 125, in view
    return self.dispatch(request, *args, **kwargs)
           ^^^^^^^^^^^^^^^^^^^^^^^^^^^^^^^^^^^^^^^
  File "D:\00-SoftWare\Python3.11\Lib\site-packages\rest_framework\views.py", line 511, in dispatch
    self.response = self.finalize_response(request, response, *args, **kwargs)
                    ^^^^^^^^^^^^^^^^^^^^^^^^^^^^^^^^^^^^^^^^^^^^^^^^^^^^^^^^^^
  File "D:\00-SoftWare\Python3.11\Lib\site-packages\rest_framework\views.py", line 423, in finalize_response
    assert isinstance(response, HttpResponseBase), (
AssertionError: Expected a `Response`, `HttpResponse` or `HttpStreamingResponse` to be returned from the view, but received a `<class 'list'>`
[2022-12-16 13:03:35,129][django.channels.server.log_action():160] [ERROR] HTTP POST /api/system/employee/export_employee_info/ 500 [0.15, 127.0.0.1:13373]
[2022-12-16 13:04:25,491][django.request.log_response():224] [ERROR] Internal Server Error: /api/system/employee/export_employee_info/
Traceback (most recent call last):
  File "D:\00-SoftWare\Python3.11\Lib\site-packages\asgiref\sync.py", line 472, in thread_handler
    raise exc_info[1]
  File "D:\00-SoftWare\Python3.11\Lib\site-packages\django\core\handlers\exception.py", line 38, in inner
    response = await get_response(request)
               ^^^^^^^^^^^^^^^^^^^^^^^^^^^
  File "D:\00-SoftWare\Python3.11\Lib\site-packages\asgiref\sync.py", line 472, in thread_handler
    raise exc_info[1]
  File "D:\00-SoftWare\Python3.11\Lib\site-packages\django\core\handlers\base.py", line 233, in _get_response_async
    response = await wrapped_callback(request, *callback_args, **callback_kwargs)
               ^^^^^^^^^^^^^^^^^^^^^^^^^^^^^^^^^^^^^^^^^^^^^^^^^^^^^^^^^^^^^^^^^^
  File "D:\00-SoftWare\Python3.11\Lib\site-packages\asgiref\sync.py", line 435, in __call__
    ret = await asyncio.wait_for(future, timeout=None)
          ^^^^^^^^^^^^^^^^^^^^^^^^^^^^^^^^^^^^^^^^^^^^
  File "D:\00-SoftWare\Python3.11\Lib\asyncio\tasks.py", line 442, in wait_for
    return await fut
           ^^^^^^^^^
  File "D:\00-SoftWare\Python3.11\Lib\site-packages\asgiref\current_thread_executor.py", line 22, in run
    result = self.fn(*self.args, **self.kwargs)
             ^^^^^^^^^^^^^^^^^^^^^^^^^^^^^^^^^^
  File "D:\00-SoftWare\Python3.11\Lib\site-packages\asgiref\sync.py", line 476, in thread_handler
    return func(*args, **kwargs)
           ^^^^^^^^^^^^^^^^^^^^^
  File "D:\00-SoftWare\Python3.11\Lib\site-packages\django\views\decorators\csrf.py", line 54, in wrapped_view
    return view_func(*args, **kwargs)
           ^^^^^^^^^^^^^^^^^^^^^^^^^^
  File "D:\00-SoftWare\Python3.11\Lib\site-packages\rest_framework\viewsets.py", line 125, in view
    return self.dispatch(request, *args, **kwargs)
           ^^^^^^^^^^^^^^^^^^^^^^^^^^^^^^^^^^^^^^^
  File "D:\00-SoftWare\Python3.11\Lib\site-packages\rest_framework\views.py", line 511, in dispatch
    self.response = self.finalize_response(request, response, *args, **kwargs)
                    ^^^^^^^^^^^^^^^^^^^^^^^^^^^^^^^^^^^^^^^^^^^^^^^^^^^^^^^^^^
  File "D:\00-SoftWare\Python3.11\Lib\site-packages\rest_framework\views.py", line 423, in finalize_response
    assert isinstance(response, HttpResponseBase), (
AssertionError: Expected a `Response`, `HttpResponse` or `HttpStreamingResponse` to be returned from the view, but received a `<class 'list'>`
[2022-12-16 13:04:25,496][django.channels.server.log_action():160] [ERROR] HTTP POST /api/system/employee/export_employee_info/ 500 [0.08, 127.0.0.1:13382]
[2022-12-16 13:05:42,215][django.request.log_response():224] [ERROR] Internal Server Error: /api/system/employee/export_employee_info/
Traceback (most recent call last):
  File "D:\00-SoftWare\Python3.11\Lib\site-packages\asgiref\sync.py", line 472, in thread_handler
    raise exc_info[1]
  File "D:\00-SoftWare\Python3.11\Lib\site-packages\django\core\handlers\exception.py", line 38, in inner
    response = await get_response(request)
               ^^^^^^^^^^^^^^^^^^^^^^^^^^^
  File "D:\00-SoftWare\Python3.11\Lib\site-packages\asgiref\sync.py", line 472, in thread_handler
    raise exc_info[1]
  File "D:\00-SoftWare\Python3.11\Lib\site-packages\django\core\handlers\base.py", line 233, in _get_response_async
    response = await wrapped_callback(request, *callback_args, **callback_kwargs)
               ^^^^^^^^^^^^^^^^^^^^^^^^^^^^^^^^^^^^^^^^^^^^^^^^^^^^^^^^^^^^^^^^^^
  File "D:\00-SoftWare\Python3.11\Lib\site-packages\asgiref\sync.py", line 435, in __call__
    ret = await asyncio.wait_for(future, timeout=None)
          ^^^^^^^^^^^^^^^^^^^^^^^^^^^^^^^^^^^^^^^^^^^^
  File "D:\00-SoftWare\Python3.11\Lib\asyncio\tasks.py", line 442, in wait_for
    return await fut
           ^^^^^^^^^
  File "D:\00-SoftWare\Python3.11\Lib\site-packages\asgiref\current_thread_executor.py", line 22, in run
    result = self.fn(*self.args, **self.kwargs)
             ^^^^^^^^^^^^^^^^^^^^^^^^^^^^^^^^^^
  File "D:\00-SoftWare\Python3.11\Lib\site-packages\asgiref\sync.py", line 476, in thread_handler
    return func(*args, **kwargs)
           ^^^^^^^^^^^^^^^^^^^^^
  File "D:\00-SoftWare\Python3.11\Lib\site-packages\django\views\decorators\csrf.py", line 54, in wrapped_view
    return view_func(*args, **kwargs)
           ^^^^^^^^^^^^^^^^^^^^^^^^^^
  File "D:\00-SoftWare\Python3.11\Lib\site-packages\rest_framework\viewsets.py", line 125, in view
    return self.dispatch(request, *args, **kwargs)
           ^^^^^^^^^^^^^^^^^^^^^^^^^^^^^^^^^^^^^^^
  File "D:\00-SoftWare\Python3.11\Lib\site-packages\rest_framework\views.py", line 511, in dispatch
    self.response = self.finalize_response(request, response, *args, **kwargs)
                    ^^^^^^^^^^^^^^^^^^^^^^^^^^^^^^^^^^^^^^^^^^^^^^^^^^^^^^^^^^
  File "D:\00-SoftWare\Python3.11\Lib\site-packages\rest_framework\views.py", line 423, in finalize_response
    assert isinstance(response, HttpResponseBase), (
AssertionError: Expected a `Response`, `HttpResponse` or `HttpStreamingResponse` to be returned from the view, but received a `<class 'list'>`
[2022-12-16 13:05:42,222][django.channels.server.log_action():160] [ERROR] HTTP POST /api/system/employee/export_employee_info/ 500 [31.32, 127.0.0.1:13382]
[2022-12-16 17:35:03,163][django.request.log_response():224] [ERROR] Internal Server Error: /api/system/employee/export_employee_info/
Traceback (most recent call last):
  File "D:\00-SoftWare\Python3.11\Lib\site-packages\asgiref\sync.py", line 472, in thread_handler
    raise exc_info[1]
  File "D:\00-SoftWare\Python3.11\Lib\site-packages\django\core\handlers\exception.py", line 38, in inner
    response = await get_response(request)
               ^^^^^^^^^^^^^^^^^^^^^^^^^^^
  File "D:\00-SoftWare\Python3.11\Lib\site-packages\asgiref\sync.py", line 472, in thread_handler
    raise exc_info[1]
  File "D:\00-SoftWare\Python3.11\Lib\site-packages\django\core\handlers\base.py", line 233, in _get_response_async
    response = await wrapped_callback(request, *callback_args, **callback_kwargs)
               ^^^^^^^^^^^^^^^^^^^^^^^^^^^^^^^^^^^^^^^^^^^^^^^^^^^^^^^^^^^^^^^^^^
  File "D:\00-SoftWare\Python3.11\Lib\site-packages\asgiref\sync.py", line 435, in __call__
    ret = await asyncio.wait_for(future, timeout=None)
          ^^^^^^^^^^^^^^^^^^^^^^^^^^^^^^^^^^^^^^^^^^^^
  File "D:\00-SoftWare\Python3.11\Lib\asyncio\tasks.py", line 442, in wait_for
    return await fut
           ^^^^^^^^^
  File "D:\00-SoftWare\Python3.11\Lib\site-packages\asgiref\current_thread_executor.py", line 22, in run
    result = self.fn(*self.args, **self.kwargs)
             ^^^^^^^^^^^^^^^^^^^^^^^^^^^^^^^^^^
  File "D:\00-SoftWare\Python3.11\Lib\site-packages\asgiref\sync.py", line 476, in thread_handler
    return func(*args, **kwargs)
           ^^^^^^^^^^^^^^^^^^^^^
  File "D:\00-SoftWare\Python3.11\Lib\site-packages\django\views\decorators\csrf.py", line 54, in wrapped_view
    return view_func(*args, **kwargs)
           ^^^^^^^^^^^^^^^^^^^^^^^^^^
  File "D:\00-SoftWare\Python3.11\Lib\site-packages\rest_framework\viewsets.py", line 125, in view
    return self.dispatch(request, *args, **kwargs)
           ^^^^^^^^^^^^^^^^^^^^^^^^^^^^^^^^^^^^^^^
  File "D:\00-SoftWare\Python3.11\Lib\site-packages\rest_framework\views.py", line 511, in dispatch
    self.response = self.finalize_response(request, response, *args, **kwargs)
                    ^^^^^^^^^^^^^^^^^^^^^^^^^^^^^^^^^^^^^^^^^^^^^^^^^^^^^^^^^^
  File "D:\00-SoftWare\Python3.11\Lib\site-packages\rest_framework\views.py", line 423, in finalize_response
    assert isinstance(response, HttpResponseBase), (
AssertionError: Expected a `Response`, `HttpResponse` or `HttpStreamingResponse` to be returned from the view, but received a `<class 'NoneType'>`
[2022-12-16 17:37:50,333][dvadmin.utils.exception.CustomExceptionHandler():46] [ERROR] Traceback (most recent call last):
  File "D:\00-SoftWare\Python3.11\Lib\site-packages\rest_framework\views.py", line 506, in dispatch
    response = handler(request, *args, **kwargs)
               ^^^^^^^^^^^^^^^^^^^^^^^^^^^^^^^^^
  File "F:\django-vue-admin\backend\dvadmin\system\views\employee.py", line 123, in export_employee_info
    doc.save(files)
  File "D:\00-SoftWare\Python3.11\Lib\site-packages\docxtpl\template.py", line 726, in save
    self.docx.save(filename, *args, **kwargs)
  File "D:\00-SoftWare\Python3.11\Lib\site-packages\docx\document.py", line 135, in save
    self._part.save(path_or_stream)
  File "D:\00-SoftWare\Python3.11\Lib\site-packages\docx\parts\document.py", line 111, in save
    self.package.save(path_or_stream)
  File "D:\00-SoftWare\Python3.11\Lib\site-packages\docx\opc\package.py", line 172, in save
    PackageWriter.write(pkg_file, self.rels, self.parts)
  File "D:\00-SoftWare\Python3.11\Lib\site-packages\docx\opc\pkgwriter.py", line 33, in write
    PackageWriter._write_content_types_stream(phys_writer, parts)
  File "D:\00-SoftWare\Python3.11\Lib\site-packages\docx\opc\pkgwriter.py", line 45, in _write_content_types_stream
    phys_writer.write(CONTENT_TYPES_URI, cti.blob)
  File "D:\00-SoftWare\Python3.11\Lib\site-packages\docx\opc\phys_pkg.py", line 155, in write
    self._zipf.writestr(pack_uri.membername, blob)
  File "D:\00-SoftWare\Python3.11\Lib\zipfile.py", line 1830, in writestr
    with self.open(zinfo, mode='w') as dest:
         ^^^^^^^^^^^^^^^^^^^^^^^^^^
  File "D:\00-SoftWare\Python3.11\Lib\zipfile.py", line 1547, in open
    return self._open_to_write(zinfo, force_zip64=force_zip64)
           ^^^^^^^^^^^^^^^^^^^^^^^^^^^^^^^^^^^^^^^^^^^^^^^^^^^
  File "D:\00-SoftWare\Python3.11\Lib\zipfile.py", line 1644, in _open_to_write
    self.fp.write(zinfo.FileHeader(zip64))
  File "D:\00-SoftWare\Python3.11\Lib\zipfile.py", line 788, in write
    n = self.fp.write(data)
        ^^^^^^^^^^^^^
AttributeError: 'list' object has no attribute 'write'

[2022-12-16 17:38:58,338][dvadmin.utils.exception.CustomExceptionHandler():46] [ERROR] Traceback (most recent call last):
  File "D:\00-SoftWare\Python3.11\Lib\site-packages\rest_framework\views.py", line 506, in dispatch
    response = handler(request, *args, **kwargs)
               ^^^^^^^^^^^^^^^^^^^^^^^^^^^^^^^^^
  File "F:\django-vue-admin\backend\dvadmin\system\views\employee.py", line 123, in export_employee_info
    doc.save(files[index])
             ~~~~~^^^^^^^
IndexError: list index out of range

[2022-12-16 17:40:34,171][dvadmin.utils.exception.CustomExceptionHandler():46] [ERROR] Traceback (most recent call last):
  File "D:\00-SoftWare\Python3.11\Lib\site-packages\rest_framework\views.py", line 506, in dispatch
    response = handler(request, *args, **kwargs)
               ^^^^^^^^^^^^^^^^^^^^^^^^^^^^^^^^^
  File "F:\django-vue-admin\backend\dvadmin\system\views\employee.py", line 123, in export_employee_info
    files.append(doc.save())
                 ^^^^^^^^^^
TypeError: DocxTemplate.save() missing 1 required positional argument: 'filename'

[2022-12-16 17:42:09,638][dvadmin.utils.exception.CustomExceptionHandler():46] [ERROR] Traceback (most recent call last):
  File "D:\00-SoftWare\Python3.11\Lib\site-packages\rest_framework\views.py", line 506, in dispatch
    response = handler(request, *args, **kwargs)
               ^^^^^^^^^^^^^^^^^^^^^^^^^^^^^^^^^
  File "F:\django-vue-admin\backend\dvadmin\system\views\employee.py", line 124, in export_employee_info
    doc.save(file_data)
  File "D:\00-SoftWare\Python3.11\Lib\site-packages\docxtpl\template.py", line 726, in save
    self.docx.save(filename, *args, **kwargs)
  File "D:\00-SoftWare\Python3.11\Lib\site-packages\docx\document.py", line 135, in save
    self._part.save(path_or_stream)
  File "D:\00-SoftWare\Python3.11\Lib\site-packages\docx\parts\document.py", line 111, in save
    self.package.save(path_or_stream)
  File "D:\00-SoftWare\Python3.11\Lib\site-packages\docx\opc\package.py", line 172, in save
    PackageWriter.write(pkg_file, self.rels, self.parts)
  File "D:\00-SoftWare\Python3.11\Lib\site-packages\docx\opc\pkgwriter.py", line 32, in write
    phys_writer = PhysPkgWriter(pkg_file)
                  ^^^^^^^^^^^^^^^^^^^^^^^
  File "D:\00-SoftWare\Python3.11\Lib\site-packages\docx\opc\phys_pkg.py", line 141, in __init__
    self._zipf = ZipFile(pkg_file, 'w', compression=ZIP_DEFLATED)
                 ^^^^^^^^^^^^^^^^^^^^^^^^^^^^^^^^^^^^^^^^^^^^^^^^
  File "D:\00-SoftWare\Python3.11\Lib\zipfile.py", line 1281, in __init__
    self.fp = io.open(file, filemode)
              ^^^^^^^^^^^^^^^^^^^^^^^
FileNotFoundError: [Errno 2] No such file or directory: ''

[2022-12-16 17:52:02,021][dvadmin.utils.exception.CustomExceptionHandler():46] [ERROR] Traceback (most recent call last):
  File "D:\00-SoftWare\Python3.11\Lib\site-packages\rest_framework\views.py", line 506, in dispatch
    response = handler(request, *args, **kwargs)
               ^^^^^^^^^^^^^^^^^^^^^^^^^^^^^^^^^
  File "F:\django-vue-admin\backend\dvadmin\system\views\employee.py", line 128, in export_employee_info
    f.write(file)
  File "D:\00-SoftWare\Python3.11\Lib\zipfile.py", line 1771, in write
    zinfo = ZipInfo.from_file(filename, arcname,
            ^^^^^^^^^^^^^^^^^^^^^^^^^^^^^^^^^^^^
  File "D:\00-SoftWare\Python3.11\Lib\zipfile.py", line 528, in from_file
    st = os.stat(filename)
         ^^^^^^^^^^^^^^^^^
ValueError: stat: embedded null character in path

[2022-12-16 17:52:13,079][dvadmin.utils.exception.CustomExceptionHandler():46] [ERROR] Traceback (most recent call last):
  File "D:\00-SoftWare\Python3.11\Lib\site-packages\rest_framework\views.py", line 506, in dispatch
    response = handler(request, *args, **kwargs)
               ^^^^^^^^^^^^^^^^^^^^^^^^^^^^^^^^^
  File "F:\django-vue-admin\backend\dvadmin\system\views\employee.py", line 128, in export_employee_info
    f.write(file)
  File "D:\00-SoftWare\Python3.11\Lib\zipfile.py", line 1771, in write
    zinfo = ZipInfo.from_file(filename, arcname,
            ^^^^^^^^^^^^^^^^^^^^^^^^^^^^^^^^^^^^
  File "D:\00-SoftWare\Python3.11\Lib\zipfile.py", line 528, in from_file
    st = os.stat(filename)
         ^^^^^^^^^^^^^^^^^
ValueError: stat: embedded null character in path

[2022-12-16 17:54:32,087][dvadmin.utils.exception.CustomExceptionHandler():46] [ERROR] Traceback (most recent call last):
  File "D:\00-SoftWare\Python3.11\Lib\site-packages\rest_framework\views.py", line 506, in dispatch
    response = handler(request, *args, **kwargs)
               ^^^^^^^^^^^^^^^^^^^^^^^^^^^^^^^^^
  File "F:\django-vue-admin\backend\dvadmin\system\views\employee.py", line 128, in export_employee_info
    f.write(file)
  File "D:\00-SoftWare\Python3.11\Lib\zipfile.py", line 1771, in write
    zinfo = ZipInfo.from_file(filename, arcname,
            ^^^^^^^^^^^^^^^^^^^^^^^^^^^^^^^^^^^^
  File "D:\00-SoftWare\Python3.11\Lib\zipfile.py", line 528, in from_file
    st = os.stat(filename)
         ^^^^^^^^^^^^^^^^^
ValueError: stat: embedded null character in path

[2022-12-18 22:54:28,732][dvadmin.utils.exception.CustomExceptionHandler():46] [ERROR] Traceback (most recent call last):
  File "D:\00-SoftWare\Python3.11\Lib\site-packages\rest_framework\views.py", line 506, in dispatch
    response = handler(request, *args, **kwargs)
               ^^^^^^^^^^^^^^^^^^^^^^^^^^^^^^^^^
  File "F:\django-vue-admin\backend\dvadmin\system\views\employee.py", line 125, in export_employee_info
    for key, value in self.field_label:
        ^^^^^^^^^^
ValueError: too many values to unpack (expected 2)

[2022-12-18 22:54:39,960][dvadmin.utils.exception.CustomExceptionHandler():46] [ERROR] Traceback (most recent call last):
  File "D:\00-SoftWare\Python3.11\Lib\site-packages\rest_framework\views.py", line 506, in dispatch
    response = handler(request, *args, **kwargs)
               ^^^^^^^^^^^^^^^^^^^^^^^^^^^^^^^^^
  File "F:\django-vue-admin\backend\dvadmin\system\views\employee.py", line 125, in export_employee_info
    for key, value in self.field_label:
        ^^^^^^^^^^
ValueError: too many values to unpack (expected 2)

[2022-12-18 22:55:19,675][dvadmin.utils.exception.CustomExceptionHandler():46] [ERROR] Traceback (most recent call last):
  File "D:\00-SoftWare\Python3.11\Lib\site-packages\rest_framework\views.py", line 506, in dispatch
    response = handler(request, *args, **kwargs)
               ^^^^^^^^^^^^^^^^^^^^^^^^^^^^^^^^^
  File "F:\django-vue-admin\backend\dvadmin\system\views\employee.py", line 125, in export_employee_info
    for key, value in self.field_label:
        ^^^^^^^^^^
ValueError: too many values to unpack (expected 2)

[2023-01-03 21:44:59,609][django.request.log_response():224] [ERROR] Internal Server Error: /
Traceback (most recent call last):
  File "D:\00-SoftWare\Python3.11\Lib\site-packages\asgiref\sync.py", line 472, in thread_handler
    raise exc_info[1]
  File "D:\00-SoftWare\Python3.11\Lib\site-packages\django\core\handlers\exception.py", line 38, in inner
    response = await get_response(request)
               ^^^^^^^^^^^^^^^^^^^^^^^^^^^
  File "D:\00-SoftWare\Python3.11\Lib\site-packages\asgiref\sync.py", line 472, in thread_handler
    raise exc_info[1]
  File "D:\00-SoftWare\Python3.11\Lib\site-packages\django\core\handlers\base.py", line 263, in _get_response_async
    response = await sync_to_async(response.render, thread_sensitive=True)()
               ^^^^^^^^^^^^^^^^^^^^^^^^^^^^^^^^^^^^^^^^^^^^^^^^^^^^^^^^^^^^^
  File "D:\00-SoftWare\Python3.11\Lib\site-packages\asgiref\sync.py", line 435, in __call__
    ret = await asyncio.wait_for(future, timeout=None)
          ^^^^^^^^^^^^^^^^^^^^^^^^^^^^^^^^^^^^^^^^^^^^
  File "D:\00-SoftWare\Python3.11\Lib\asyncio\tasks.py", line 442, in wait_for
    return await fut
           ^^^^^^^^^
  File "D:\00-SoftWare\Python3.11\Lib\site-packages\asgiref\current_thread_executor.py", line 22, in run
    result = self.fn(*self.args, **self.kwargs)
             ^^^^^^^^^^^^^^^^^^^^^^^^^^^^^^^^^^
  File "D:\00-SoftWare\Python3.11\Lib\site-packages\asgiref\sync.py", line 476, in thread_handler
    return func(*args, **kwargs)
           ^^^^^^^^^^^^^^^^^^^^^
  File "D:\00-SoftWare\Python3.11\Lib\site-packages\django\template\response.py", line 105, in render
    self.content = self.rendered_content
                   ^^^^^^^^^^^^^^^^^^^^^
  File "D:\00-SoftWare\Python3.11\Lib\site-packages\rest_framework\response.py", line 70, in rendered_content
    ret = renderer.render(self.data, accepted_media_type, context)
          ^^^^^^^^^^^^^^^^^^^^^^^^^^^^^^^^^^^^^^^^^^^^^^^^^^^^^^^^
  File "D:\00-SoftWare\Python3.11\Lib\site-packages\drf_yasg\renderers.py", line 73, in render
    return render_to_string(self.template, renderer_context, renderer_context['request'])
           ^^^^^^^^^^^^^^^^^^^^^^^^^^^^^^^^^^^^^^^^^^^^^^^^^^^^^^^^^^^^^^^^^^^^^^^^^^^^^^
  File "D:\00-SoftWare\Python3.11\Lib\site-packages\django\template\loader.py", line 62, in render_to_string
    return template.render(context, request)
           ^^^^^^^^^^^^^^^^^^^^^^^^^^^^^^^^^
  File "D:\00-SoftWare\Python3.11\Lib\site-packages\django\template\backends\django.py", line 61, in render
    return self.template.render(context)
           ^^^^^^^^^^^^^^^^^^^^^^^^^^^^^
  File "D:\00-SoftWare\Python3.11\Lib\site-packages\django\template\base.py", line 168, in render
    with context.bind_template(self):
  File "D:\00-SoftWare\Python3.11\Lib\contextlib.py", line 137, in __enter__
    return next(self.gen)
           ^^^^^^^^^^^^^^
  File "D:\00-SoftWare\Python3.11\Lib\site-packages\django\template\context.py", line 240, in bind_template
    processors = (template.engine.template_context_processors +
                  ^^^^^^^^^^^^^^^^^^^^^^^^^^^^^^^^^^^^^^^^^^^
  File "D:\00-SoftWare\Python3.11\Lib\site-packages\django\utils\functional.py", line 48, in __get__
    res = instance.__dict__[self.name] = self.func(instance)
                                         ^^^^^^^^^^^^^^^^^^^
  File "D:\00-SoftWare\Python3.11\Lib\site-packages\django\template\engine.py", line 85, in template_context_processors
    return tuple(import_string(path) for path in context_processors)
           ^^^^^^^^^^^^^^^^^^^^^^^^^^^^^^^^^^^^^^^^^^^^^^^^^^^^^^^^^
  File "D:\00-SoftWare\Python3.11\Lib\site-packages\django\template\engine.py", line 85, in <genexpr>
    return tuple(import_string(path) for path in context_processors)
                 ^^^^^^^^^^^^^^^^^^^
  File "D:\00-SoftWare\Python3.11\Lib\site-packages\django\utils\module_loading.py", line 17, in import_string
    module = import_module(module_path)
             ^^^^^^^^^^^^^^^^^^^^^^^^^^
  File "D:\00-SoftWare\Python3.11\Lib\importlib\__init__.py", line 126, in import_module
    return _bootstrap._gcd_import(name[level:], package, level)
           ^^^^^^^^^^^^^^^^^^^^^^^^^^^^^^^^^^^^^^^^^^^^^^^^^^^^
  File "<frozen importlib._bootstrap>", line 1206, in _gcd_import
  File "<frozen importlib._bootstrap>", line 1178, in _find_and_load
  File "<frozen importlib._bootstrap>", line 1149, in _find_and_load_unlocked
  File "<frozen importlib._bootstrap>", line 690, in _load_unlocked
  File "<frozen importlib._bootstrap_external>", line 936, in exec_module
  File "<frozen importlib._bootstrap_external>", line 1074, in get_code
  File "<frozen importlib._bootstrap_external>", line 1004, in source_to_code
  File "<frozen importlib._bootstrap>", line 241, in _call_with_frames_removed
  File "F:\django-vue-admin\backend\conf\svn.py", line 3
    'SVN_URL': 'http://10.65.7.148/svn/LNcrm/ln-doc/�����ƶ�ϵͳ����',
                                                                   ^
SyntaxError: (unicode error) 'utf-8' codec can't decode byte 0xc1 in position 36: invalid start byte
[2023-01-03 21:44:59,699][django.channels.server.log_action():160] [ERROR] HTTP GET / 500 [0.13, 127.0.0.1:10210]
[2023-01-03 21:45:19,628][django.request.log_response():224] [ERROR] Internal Server Error: /
Traceback (most recent call last):
  File "D:\00-SoftWare\Python3.11\Lib\site-packages\asgiref\sync.py", line 472, in thread_handler
    raise exc_info[1]
  File "D:\00-SoftWare\Python3.11\Lib\site-packages\django\core\handlers\exception.py", line 38, in inner
    response = await get_response(request)
               ^^^^^^^^^^^^^^^^^^^^^^^^^^^
  File "D:\00-SoftWare\Python3.11\Lib\site-packages\asgiref\sync.py", line 472, in thread_handler
    raise exc_info[1]
  File "D:\00-SoftWare\Python3.11\Lib\site-packages\django\core\handlers\base.py", line 263, in _get_response_async
    response = await sync_to_async(response.render, thread_sensitive=True)()
               ^^^^^^^^^^^^^^^^^^^^^^^^^^^^^^^^^^^^^^^^^^^^^^^^^^^^^^^^^^^^^
  File "D:\00-SoftWare\Python3.11\Lib\site-packages\asgiref\sync.py", line 435, in __call__
    ret = await asyncio.wait_for(future, timeout=None)
          ^^^^^^^^^^^^^^^^^^^^^^^^^^^^^^^^^^^^^^^^^^^^
  File "D:\00-SoftWare\Python3.11\Lib\asyncio\tasks.py", line 442, in wait_for
    return await fut
           ^^^^^^^^^
  File "D:\00-SoftWare\Python3.11\Lib\site-packages\asgiref\current_thread_executor.py", line 22, in run
    result = self.fn(*self.args, **self.kwargs)
             ^^^^^^^^^^^^^^^^^^^^^^^^^^^^^^^^^^
  File "D:\00-SoftWare\Python3.11\Lib\site-packages\asgiref\sync.py", line 476, in thread_handler
    return func(*args, **kwargs)
           ^^^^^^^^^^^^^^^^^^^^^
  File "D:\00-SoftWare\Python3.11\Lib\site-packages\django\template\response.py", line 105, in render
    self.content = self.rendered_content
                   ^^^^^^^^^^^^^^^^^^^^^
  File "D:\00-SoftWare\Python3.11\Lib\site-packages\rest_framework\response.py", line 70, in rendered_content
    ret = renderer.render(self.data, accepted_media_type, context)
          ^^^^^^^^^^^^^^^^^^^^^^^^^^^^^^^^^^^^^^^^^^^^^^^^^^^^^^^^
  File "D:\00-SoftWare\Python3.11\Lib\site-packages\drf_yasg\renderers.py", line 73, in render
    return render_to_string(self.template, renderer_context, renderer_context['request'])
           ^^^^^^^^^^^^^^^^^^^^^^^^^^^^^^^^^^^^^^^^^^^^^^^^^^^^^^^^^^^^^^^^^^^^^^^^^^^^^^
  File "D:\00-SoftWare\Python3.11\Lib\site-packages\django\template\loader.py", line 62, in render_to_string
    return template.render(context, request)
           ^^^^^^^^^^^^^^^^^^^^^^^^^^^^^^^^^
  File "D:\00-SoftWare\Python3.11\Lib\site-packages\django\template\backends\django.py", line 61, in render
    return self.template.render(context)
           ^^^^^^^^^^^^^^^^^^^^^^^^^^^^^
  File "D:\00-SoftWare\Python3.11\Lib\site-packages\django\template\base.py", line 168, in render
    with context.bind_template(self):
  File "D:\00-SoftWare\Python3.11\Lib\contextlib.py", line 137, in __enter__
    return next(self.gen)
           ^^^^^^^^^^^^^^
  File "D:\00-SoftWare\Python3.11\Lib\site-packages\django\template\context.py", line 240, in bind_template
    processors = (template.engine.template_context_processors +
                  ^^^^^^^^^^^^^^^^^^^^^^^^^^^^^^^^^^^^^^^^^^^
  File "D:\00-SoftWare\Python3.11\Lib\site-packages\django\utils\functional.py", line 48, in __get__
    res = instance.__dict__[self.name] = self.func(instance)
                                         ^^^^^^^^^^^^^^^^^^^
  File "D:\00-SoftWare\Python3.11\Lib\site-packages\django\template\engine.py", line 85, in template_context_processors
    return tuple(import_string(path) for path in context_processors)
           ^^^^^^^^^^^^^^^^^^^^^^^^^^^^^^^^^^^^^^^^^^^^^^^^^^^^^^^^^
  File "D:\00-SoftWare\Python3.11\Lib\site-packages\django\template\engine.py", line 85, in <genexpr>
    return tuple(import_string(path) for path in context_processors)
                 ^^^^^^^^^^^^^^^^^^^
  File "D:\00-SoftWare\Python3.11\Lib\site-packages\django\utils\module_loading.py", line 17, in import_string
    module = import_module(module_path)
             ^^^^^^^^^^^^^^^^^^^^^^^^^^
  File "D:\00-SoftWare\Python3.11\Lib\importlib\__init__.py", line 126, in import_module
    return _bootstrap._gcd_import(name[level:], package, level)
           ^^^^^^^^^^^^^^^^^^^^^^^^^^^^^^^^^^^^^^^^^^^^^^^^^^^^
  File "<frozen importlib._bootstrap>", line 1206, in _gcd_import
  File "<frozen importlib._bootstrap>", line 1178, in _find_and_load
  File "<frozen importlib._bootstrap>", line 1149, in _find_and_load_unlocked
  File "<frozen importlib._bootstrap>", line 690, in _load_unlocked
  File "<frozen importlib._bootstrap_external>", line 936, in exec_module
  File "<frozen importlib._bootstrap_external>", line 1074, in get_code
  File "<frozen importlib._bootstrap_external>", line 1004, in source_to_code
  File "<frozen importlib._bootstrap>", line 241, in _call_with_frames_removed
  File "F:\django-vue-admin\backend\conf\svn.py", line 3
    'SVN_URL': 'http://10.65.7.148/svn/LNcrm/ln-doc/�����ƶ�ϵͳ����',
                                                                   ^
SyntaxError: (unicode error) 'utf-8' codec can't decode byte 0xc1 in position 36: invalid start byte
[2023-01-03 21:45:19,635][django.channels.server.log_action():160] [ERROR] HTTP GET / 500 [0.04, 127.0.0.1:10242]
[2023-01-03 21:45:48,443][django.request.log_response():224] [ERROR] Internal Server Error: /
Traceback (most recent call last):
  File "D:\00-SoftWare\Python3.11\Lib\site-packages\asgiref\sync.py", line 472, in thread_handler
    raise exc_info[1]
  File "D:\00-SoftWare\Python3.11\Lib\site-packages\django\core\handlers\exception.py", line 38, in inner
    response = await get_response(request)
               ^^^^^^^^^^^^^^^^^^^^^^^^^^^
  File "D:\00-SoftWare\Python3.11\Lib\site-packages\asgiref\sync.py", line 472, in thread_handler
    raise exc_info[1]
  File "D:\00-SoftWare\Python3.11\Lib\site-packages\django\core\handlers\base.py", line 263, in _get_response_async
    response = await sync_to_async(response.render, thread_sensitive=True)()
               ^^^^^^^^^^^^^^^^^^^^^^^^^^^^^^^^^^^^^^^^^^^^^^^^^^^^^^^^^^^^^
  File "D:\00-SoftWare\Python3.11\Lib\site-packages\asgiref\sync.py", line 435, in __call__
    ret = await asyncio.wait_for(future, timeout=None)
          ^^^^^^^^^^^^^^^^^^^^^^^^^^^^^^^^^^^^^^^^^^^^
  File "D:\00-SoftWare\Python3.11\Lib\asyncio\tasks.py", line 442, in wait_for
    return await fut
           ^^^^^^^^^
  File "D:\00-SoftWare\Python3.11\Lib\site-packages\asgiref\current_thread_executor.py", line 22, in run
    result = self.fn(*self.args, **self.kwargs)
             ^^^^^^^^^^^^^^^^^^^^^^^^^^^^^^^^^^
  File "D:\00-SoftWare\Python3.11\Lib\site-packages\asgiref\sync.py", line 476, in thread_handler
    return func(*args, **kwargs)
           ^^^^^^^^^^^^^^^^^^^^^
  File "D:\00-SoftWare\Python3.11\Lib\site-packages\django\template\response.py", line 105, in render
    self.content = self.rendered_content
                   ^^^^^^^^^^^^^^^^^^^^^
  File "D:\00-SoftWare\Python3.11\Lib\site-packages\rest_framework\response.py", line 70, in rendered_content
    ret = renderer.render(self.data, accepted_media_type, context)
          ^^^^^^^^^^^^^^^^^^^^^^^^^^^^^^^^^^^^^^^^^^^^^^^^^^^^^^^^
  File "D:\00-SoftWare\Python3.11\Lib\site-packages\drf_yasg\renderers.py", line 73, in render
    return render_to_string(self.template, renderer_context, renderer_context['request'])
           ^^^^^^^^^^^^^^^^^^^^^^^^^^^^^^^^^^^^^^^^^^^^^^^^^^^^^^^^^^^^^^^^^^^^^^^^^^^^^^
  File "D:\00-SoftWare\Python3.11\Lib\site-packages\django\template\loader.py", line 62, in render_to_string
    return template.render(context, request)
           ^^^^^^^^^^^^^^^^^^^^^^^^^^^^^^^^^
  File "D:\00-SoftWare\Python3.11\Lib\site-packages\django\template\backends\django.py", line 61, in render
    return self.template.render(context)
           ^^^^^^^^^^^^^^^^^^^^^^^^^^^^^
  File "D:\00-SoftWare\Python3.11\Lib\site-packages\django\template\base.py", line 168, in render
    with context.bind_template(self):
  File "D:\00-SoftWare\Python3.11\Lib\contextlib.py", line 137, in __enter__
    return next(self.gen)
           ^^^^^^^^^^^^^^
  File "D:\00-SoftWare\Python3.11\Lib\site-packages\django\template\context.py", line 244, in bind_template
    updates.update(processor(self.request))
                   ^^^^^^^^^^^^^^^^^^^^^^^
TypeError: svn_report() takes 0 positional arguments but 1 was given
[2023-01-03 21:45:48,445][django.channels.server.log_action():160] [ERROR] HTTP GET / 500 [0.03, 127.0.0.1:10242]
[2023-01-03 21:50:18,225][django.request.log_response():224] [ERROR] Internal Server Error: /api/project/online_version/select_version_number/
Traceback (most recent call last):
  File "D:\00-SoftWare\Python3.11\Lib\site-packages\asgiref\sync.py", line 472, in thread_handler
    raise exc_info[1]
  File "D:\00-SoftWare\Python3.11\Lib\site-packages\django\core\handlers\exception.py", line 38, in inner
    response = await get_response(request)
               ^^^^^^^^^^^^^^^^^^^^^^^^^^^
  File "D:\00-SoftWare\Python3.11\Lib\site-packages\asgiref\sync.py", line 472, in thread_handler
    raise exc_info[1]
  File "D:\00-SoftWare\Python3.11\Lib\site-packages\django\core\handlers\base.py", line 233, in _get_response_async
    response = await wrapped_callback(request, *callback_args, **callback_kwargs)
               ^^^^^^^^^^^^^^^^^^^^^^^^^^^^^^^^^^^^^^^^^^^^^^^^^^^^^^^^^^^^^^^^^^
  File "D:\00-SoftWare\Python3.11\Lib\site-packages\asgiref\sync.py", line 435, in __call__
    ret = await asyncio.wait_for(future, timeout=None)
          ^^^^^^^^^^^^^^^^^^^^^^^^^^^^^^^^^^^^^^^^^^^^
  File "D:\00-SoftWare\Python3.11\Lib\asyncio\tasks.py", line 442, in wait_for
    return await fut
           ^^^^^^^^^
  File "D:\00-SoftWare\Python3.11\Lib\site-packages\asgiref\current_thread_executor.py", line 22, in run
    result = self.fn(*self.args, **self.kwargs)
             ^^^^^^^^^^^^^^^^^^^^^^^^^^^^^^^^^^
  File "D:\00-SoftWare\Python3.11\Lib\site-packages\asgiref\sync.py", line 476, in thread_handler
    return func(*args, **kwargs)
           ^^^^^^^^^^^^^^^^^^^^^
  File "D:\00-SoftWare\Python3.11\Lib\site-packages\django\views\decorators\csrf.py", line 54, in wrapped_view
    return view_func(*args, **kwargs)
           ^^^^^^^^^^^^^^^^^^^^^^^^^^
  File "D:\00-SoftWare\Python3.11\Lib\site-packages\rest_framework\viewsets.py", line 125, in view
    return self.dispatch(request, *args, **kwargs)
           ^^^^^^^^^^^^^^^^^^^^^^^^^^^^^^^^^^^^^^^
  File "D:\00-SoftWare\Python3.11\Lib\site-packages\rest_framework\views.py", line 511, in dispatch
    self.response = self.finalize_response(request, response, *args, **kwargs)
                    ^^^^^^^^^^^^^^^^^^^^^^^^^^^^^^^^^^^^^^^^^^^^^^^^^^^^^^^^^^
  File "D:\00-SoftWare\Python3.11\Lib\site-packages\rest_framework\views.py", line 423, in finalize_response
    assert isinstance(response, HttpResponseBase), (
AssertionError: Expected a `Response`, `HttpResponse` or `HttpStreamingResponse` to be returned from the view, but received a `<class 'NoneType'>`
[2023-01-03 21:50:18,233][django.channels.server.log_action():160] [ERROR] HTTP POST /api/project/online_version/select_version_number/ 500 [40.90, 127.0.0.1:10479]
[2023-01-03 22:01:50,980][django.request.log_response():224] [ERROR] Internal Server Error: /api/project/online_version/select_version_number/
Traceback (most recent call last):
  File "D:\00-SoftWare\Python3.11\Lib\site-packages\asgiref\sync.py", line 472, in thread_handler
    raise exc_info[1]
  File "D:\00-SoftWare\Python3.11\Lib\site-packages\django\core\handlers\exception.py", line 38, in inner
    response = await get_response(request)
               ^^^^^^^^^^^^^^^^^^^^^^^^^^^
  File "D:\00-SoftWare\Python3.11\Lib\site-packages\asgiref\sync.py", line 472, in thread_handler
    raise exc_info[1]
  File "D:\00-SoftWare\Python3.11\Lib\site-packages\django\core\handlers\base.py", line 233, in _get_response_async
    response = await wrapped_callback(request, *callback_args, **callback_kwargs)
               ^^^^^^^^^^^^^^^^^^^^^^^^^^^^^^^^^^^^^^^^^^^^^^^^^^^^^^^^^^^^^^^^^^
  File "D:\00-SoftWare\Python3.11\Lib\site-packages\asgiref\sync.py", line 435, in __call__
    ret = await asyncio.wait_for(future, timeout=None)
          ^^^^^^^^^^^^^^^^^^^^^^^^^^^^^^^^^^^^^^^^^^^^
  File "D:\00-SoftWare\Python3.11\Lib\asyncio\tasks.py", line 442, in wait_for
    return await fut
           ^^^^^^^^^
  File "D:\00-SoftWare\Python3.11\Lib\site-packages\asgiref\current_thread_executor.py", line 22, in run
    result = self.fn(*self.args, **self.kwargs)
             ^^^^^^^^^^^^^^^^^^^^^^^^^^^^^^^^^^
  File "D:\00-SoftWare\Python3.11\Lib\site-packages\asgiref\sync.py", line 476, in thread_handler
    return func(*args, **kwargs)
           ^^^^^^^^^^^^^^^^^^^^^
  File "D:\00-SoftWare\Python3.11\Lib\site-packages\django\views\decorators\csrf.py", line 54, in wrapped_view
    return view_func(*args, **kwargs)
           ^^^^^^^^^^^^^^^^^^^^^^^^^^
  File "D:\00-SoftWare\Python3.11\Lib\site-packages\rest_framework\viewsets.py", line 125, in view
    return self.dispatch(request, *args, **kwargs)
           ^^^^^^^^^^^^^^^^^^^^^^^^^^^^^^^^^^^^^^^
  File "D:\00-SoftWare\Python3.11\Lib\site-packages\rest_framework\views.py", line 511, in dispatch
    self.response = self.finalize_response(request, response, *args, **kwargs)
                    ^^^^^^^^^^^^^^^^^^^^^^^^^^^^^^^^^^^^^^^^^^^^^^^^^^^^^^^^^^
  File "D:\00-SoftWare\Python3.11\Lib\site-packages\rest_framework\views.py", line 423, in finalize_response
    assert isinstance(response, HttpResponseBase), (
AssertionError: Expected a `Response`, `HttpResponse` or `HttpStreamingResponse` to be returned from the view, but received a `<class 'dict'>`
[2023-01-03 22:01:50,989][django.channels.server.log_action():160] [ERROR] HTTP POST /api/project/online_version/select_version_number/ 500 [16.76, 127.0.0.1:10722]
[2023-01-03 22:11:04,481][dvadmin.utils.exception.CustomExceptionHandler():46] [ERROR] Traceback (most recent call last):
  File "D:\00-SoftWare\Python3.11\Lib\site-packages\rest_framework\views.py", line 506, in dispatch
    response = handler(request, *args, **kwargs)
               ^^^^^^^^^^^^^^^^^^^^^^^^^^^^^^^^^
  File "F:\django-vue-admin\backend\dvadmin\project\views\online_version.py", line 67, in select_version_number
    year = request.data.split('-')[0]
           ^^^^^^^^^^^^^^^^^^
AttributeError: 'dict' object has no attribute 'split'

[2023-01-06 15:16:20,359][dvadmin.utils.exception.CustomExceptionHandler():46] [ERROR] Traceback (most recent call last):
  File "D:\00-SoftWare\Python3.11\Lib\site-packages\rest_framework\views.py", line 506, in dispatch
    response = handler(request, *args, **kwargs)
               ^^^^^^^^^^^^^^^^^^^^^^^^^^^^^^^^^
  File "F:\django-vue-admin\backend\dvadmin\project\views\online_version.py", line 70, in select_version_number
    svn_dir = svn_dir_name % year, month
              ~~~~~~~~~~~~~^~~~~~
TypeError: not enough arguments for format string

[2023-01-06 15:16:24,406][dvadmin.utils.exception.CustomExceptionHandler():46] [ERROR] Traceback (most recent call last):
  File "D:\00-SoftWare\Python3.11\Lib\site-packages\rest_framework\views.py", line 506, in dispatch
    response = handler(request, *args, **kwargs)
               ^^^^^^^^^^^^^^^^^^^^^^^^^^^^^^^^^
  File "F:\django-vue-admin\backend\dvadmin\project\views\online_version.py", line 70, in select_version_number
    svn_dir = svn_dir_name % year, month
              ~~~~~~~~~~~~~^~~~~~
TypeError: not enough arguments for format string

[2023-01-06 15:16:48,114][dvadmin.utils.exception.CustomExceptionHandler():46] [ERROR] Traceback (most recent call last):
  File "D:\00-SoftWare\Python3.11\Lib\site-packages\rest_framework\views.py", line 506, in dispatch
    response = handler(request, *args, **kwargs)
               ^^^^^^^^^^^^^^^^^^^^^^^^^^^^^^^^^
  File "F:\django-vue-admin\backend\dvadmin\project\views\online_version.py", line 70, in select_version_number
    svn_dir = svn_dir_name % year, month
              ~~~~~~~~~~~~~^~~~~~
TypeError: not enough arguments for format string

[2023-01-06 15:26:26,019][dvadmin.utils.exception.CustomExceptionHandler():46] [ERROR] Traceback (most recent call last):
  File "D:\00-SoftWare\Python3.11\Lib\site-packages\rest_framework\views.py", line 506, in dispatch
    response = handler(request, *args, **kwargs)
               ^^^^^^^^^^^^^^^^^^^^^^^^^^^^^^^^^
  File "F:\django-vue-admin\backend\dvadmin\project\views\online_version.py", line 74, in select_version_number
    cmd = 'svn list ' + svn_address + ' >> ' + locale_path + '\static\svn.txt'
          ~~~~~~~~~~~~^~~~~~~~~~~~~
TypeError: can only concatenate str (not "tuple") to str

[2023-01-06 15:27:11,308][dvadmin.utils.exception.CustomExceptionHandler():46] [ERROR] Traceback (most recent call last):
  File "D:\00-SoftWare\Python3.11\Lib\site-packages\rest_framework\views.py", line 506, in dispatch
    response = handler(request, *args, **kwargs)
               ^^^^^^^^^^^^^^^^^^^^^^^^^^^^^^^^^
  File "F:\django-vue-admin\backend\dvadmin\project\views\online_version.py", line 73, in select_version_number
    cmd = 'svn list ' + svn_address + ' >> ' + locale_path + '\static\svn.txt'
          ~~~~~~~~~~~~^~~~~~~~~~~~~
TypeError: can only concatenate str (not "tuple") to str

[2023-01-06 15:27:26,527][dvadmin.utils.exception.CustomExceptionHandler():46] [ERROR] Traceback (most recent call last):
  File "D:\00-SoftWare\Python3.11\Lib\site-packages\rest_framework\views.py", line 506, in dispatch
    response = handler(request, *args, **kwargs)
               ^^^^^^^^^^^^^^^^^^^^^^^^^^^^^^^^^
  File "F:\django-vue-admin\backend\dvadmin\project\views\online_version.py", line 73, in select_version_number
    cmd = 'svn list ' + svn_address + ' >> ' + str(locale_path) + '\static\svn.txt'
          ~~~~~~~~~~~~^~~~~~~~~~~~~
TypeError: can only concatenate str (not "tuple") to str

[2023-01-06 15:27:31,224][dvadmin.utils.exception.CustomExceptionHandler():46] [ERROR] Traceback (most recent call last):
  File "D:\00-SoftWare\Python3.11\Lib\site-packages\rest_framework\views.py", line 506, in dispatch
    response = handler(request, *args, **kwargs)
               ^^^^^^^^^^^^^^^^^^^^^^^^^^^^^^^^^
  File "F:\django-vue-admin\backend\dvadmin\project\views\online_version.py", line 73, in select_version_number
    cmd = 'svn list ' + svn_address + ' >> ' + str(locale_path) + '\static\svn.txt'
          ~~~~~~~~~~~~^~~~~~~~~~~~~
TypeError: can only concatenate str (not "tuple") to str

[2023-01-07 11:35:08,070][dvadmin.utils.exception.CustomExceptionHandler():46] [ERROR] Traceback (most recent call last):
  File "D:\00-SoftWare\Python3.11\Lib\site-packages\rest_framework\views.py", line 506, in dispatch
    response = handler(request, *args, **kwargs)
               ^^^^^^^^^^^^^^^^^^^^^^^^^^^^^^^^^
  File "F:\django-vue-admin\backend\dvadmin\project\views\online_version.py", line 74, in select_version_number
    file_name_ls = [line.strip() for line in open('static/svn.txt', encoding='gbk')]    # 获取目录下的所有文件名
                                             ^^^^^^^^^^^^^^^^^^^^^^^^^^^^^^^^^^^^^^
FileNotFoundError: [Errno 2] No such file or directory: 'static/svn.txt'

[2023-01-07 11:35:48,983][dvadmin.utils.exception.CustomExceptionHandler():46] [ERROR] Traceback (most recent call last):
  File "D:\00-SoftWare\Python3.11\Lib\site-packages\rest_framework\views.py", line 506, in dispatch
    response = handler(request, *args, **kwargs)
               ^^^^^^^^^^^^^^^^^^^^^^^^^^^^^^^^^
  File "F:\django-vue-admin\backend\dvadmin\project\views\online_version.py", line 69, in select_version_number
    year = request.data['yearMonth'].split('-')[0]
           ^^^^^^^^^^^^^^^^^^^^^^^^^^^^^^^
AttributeError: 'NoneType' object has no attribute 'split'

[2023-01-07 11:35:59,090][dvadmin.utils.exception.CustomExceptionHandler():46] [ERROR] Traceback (most recent call last):
  File "D:\00-SoftWare\Python3.11\Lib\site-packages\rest_framework\views.py", line 506, in dispatch
    response = handler(request, *args, **kwargs)
               ^^^^^^^^^^^^^^^^^^^^^^^^^^^^^^^^^
  File "F:\django-vue-admin\backend\dvadmin\project\views\online_version.py", line 74, in select_version_number
    file_name_ls = [line.strip() for line in open('\static\svn_file_info.txt', encoding='gbk')]    # 获取目录下的所有文件名
                                             ^^^^^^^^^^^^^^^^^^^^^^^^^^^^^^^^^^^^^^^^^^^^^^^^^
FileNotFoundError: [Errno 2] No such file or directory: '\\static\\svn_file_info.txt'

[2023-01-07 11:37:43,563][dvadmin.utils.exception.CustomExceptionHandler():46] [ERROR] Traceback (most recent call last):
  File "D:\00-SoftWare\Python3.11\Lib\site-packages\rest_framework\views.py", line 506, in dispatch
    response = handler(request, *args, **kwargs)
               ^^^^^^^^^^^^^^^^^^^^^^^^^^^^^^^^^
  File "F:\django-vue-admin\backend\dvadmin\project\views\online_version.py", line 69, in select_version_number
    year = request.data['yearMonth'].split('-')[0]
           ^^^^^^^^^^^^^^^^^^^^^^^^^^^^^^^
AttributeError: 'NoneType' object has no attribute 'split'

[2023-01-07 11:38:21,329][dvadmin.utils.exception.CustomExceptionHandler():46] [ERROR] Traceback (most recent call last):
  File "D:\00-SoftWare\Python3.11\Lib\site-packages\rest_framework\views.py", line 506, in dispatch
    response = handler(request, *args, **kwargs)
               ^^^^^^^^^^^^^^^^^^^^^^^^^^^^^^^^^
  File "F:\django-vue-admin\backend\dvadmin\project\views\online_version.py", line 74, in select_version_number
    file_name_ls = [line.strip() for line in open('static/svn_file_info.txt', encoding='gbk')]    # 获取目录下的所有文件名
                                             ^^^^^^^^^^^^^^^^^^^^^^^^^^^^^^^^^^^^^^^^^^^^^^^^
FileNotFoundError: [Errno 2] No such file or directory: 'static/svn_file_info.txt'

[2023-01-07 11:39:26,975][dvadmin.utils.exception.CustomExceptionHandler():46] [ERROR] Traceback (most recent call last):
  File "D:\00-SoftWare\Python3.11\Lib\site-packages\rest_framework\views.py", line 506, in dispatch
    response = handler(request, *args, **kwargs)
               ^^^^^^^^^^^^^^^^^^^^^^^^^^^^^^^^^
  File "F:\django-vue-admin\backend\dvadmin\project\views\online_version.py", line 74, in select_version_number
    file_name_ls = [line.strip() for line in open('static/svn_file_info.txt', encoding='gbk')]    # 获取目录下的所有文件名
                                             ^^^^^^^^^^^^^^^^^^^^^^^^^^^^^^^^^^^^^^^^^^^^^^^^
FileNotFoundError: [Errno 2] No such file or directory: 'static/svn_file_info.txt'

[2023-01-07 11:39:35,266][dvadmin.utils.exception.CustomExceptionHandler():46] [ERROR] Traceback (most recent call last):
  File "D:\00-SoftWare\Python3.11\Lib\site-packages\rest_framework\views.py", line 506, in dispatch
    response = handler(request, *args, **kwargs)
               ^^^^^^^^^^^^^^^^^^^^^^^^^^^^^^^^^
  File "F:\django-vue-admin\backend\dvadmin\project\views\online_version.py", line 69, in select_version_number
    year = request.data['yearMonth'].split('-')[0]
           ^^^^^^^^^^^^^^^^^^^^^^^^^^^^^^^
AttributeError: 'NoneType' object has no attribute 'split'

[2023-01-07 11:40:38,520][dvadmin.utils.exception.CustomExceptionHandler():46] [ERROR] Traceback (most recent call last):
  File "D:\00-SoftWare\Python3.11\Lib\site-packages\rest_framework\views.py", line 506, in dispatch
    response = handler(request, *args, **kwargs)
               ^^^^^^^^^^^^^^^^^^^^^^^^^^^^^^^^^
  File "F:\django-vue-admin\backend\dvadmin\project\views\online_version.py", line 74, in select_version_number
    file_name_ls = [line.strip() for line in open('static/svn_file_info.txt', encoding='gbk')]    # 获取目录下的所有文件名
                                             ^^^^^^^^^^^^^^^^^^^^^^^^^^^^^^^^^^^^^^^^^^^^^^^^
FileNotFoundError: [Errno 2] No such file or directory: 'static/svn_file_info.txt'

[2023-01-07 11:41:11,563][dvadmin.utils.exception.CustomExceptionHandler():46] [ERROR] Traceback (most recent call last):
  File "D:\00-SoftWare\Python3.11\Lib\site-packages\rest_framework\views.py", line 506, in dispatch
    response = handler(request, *args, **kwargs)
               ^^^^^^^^^^^^^^^^^^^^^^^^^^^^^^^^^
  File "F:\django-vue-admin\backend\dvadmin\project\views\online_version.py", line 74, in select_version_number
    file_name_ls = [line.strip() for line in open('static/svn_file_info.txt', encoding='gbk')]    # 获取目录下的所有文件名
                                             ^^^^^^^^^^^^^^^^^^^^^^^^^^^^^^^^^^^^^^^^^^^^^^^^
FileNotFoundError: [Errno 2] No such file or directory: 'static/svn_file_info.txt'

[2023-01-07 11:41:35,515][dvadmin.utils.exception.CustomExceptionHandler():46] [ERROR] Traceback (most recent call last):
  File "D:\00-SoftWare\Python3.11\Lib\site-packages\rest_framework\views.py", line 506, in dispatch
    response = handler(request, *args, **kwargs)
               ^^^^^^^^^^^^^^^^^^^^^^^^^^^^^^^^^
  File "F:\django-vue-admin\backend\dvadmin\project\views\online_version.py", line 69, in select_version_number
    year = request.data['yearMonth'].split('-')[0]
           ^^^^^^^^^^^^^^^^^^^^^^^^^^^^^^^
AttributeError: 'NoneType' object has no attribute 'split'

[2023-01-07 11:42:01,736][dvadmin.utils.exception.CustomExceptionHandler():46] [ERROR] Traceback (most recent call last):
  File "D:\00-SoftWare\Python3.11\Lib\site-packages\rest_framework\views.py", line 506, in dispatch
    response = handler(request, *args, **kwargs)
               ^^^^^^^^^^^^^^^^^^^^^^^^^^^^^^^^^
  File "F:\django-vue-admin\backend\dvadmin\project\views\online_version.py", line 69, in select_version_number
    year = request.data['yearMonth'].split('-')[0]
           ^^^^^^^^^^^^^^^^^^^^^^^^^^^^^^^
AttributeError: 'NoneType' object has no attribute 'split'

[2023-01-09 11:46:15,652][dvadmin.utils.exception.CustomExceptionHandler():46] [ERROR] Traceback (most recent call last):
  File "D:\00-SoftWare\Python3.11\Lib\site-packages\django\db\models\fields\__init__.py", line 1823, in get_prep_value
    return int(value)
           ^^^^^^^^^^
ValueError: invalid literal for int() with base 10: 'search_by_online_version'

The above exception was the direct cause of the following exception:

Traceback (most recent call last):
  File "D:\00-SoftWare\Python3.11\Lib\site-packages\rest_framework\generics.py", line 19, in get_object_or_404
    return _get_object_or_404(queryset, *filter_args, **filter_kwargs)
           ^^^^^^^^^^^^^^^^^^^^^^^^^^^^^^^^^^^^^^^^^^^^^^^^^^^^^^^^^^^
  File "D:\00-SoftWare\Python3.11\Lib\site-packages\django\shortcuts.py", line 76, in get_object_or_404
    return queryset.get(*args, **kwargs)
           ^^^^^^^^^^^^^^^^^^^^^^^^^^^^^
  File "D:\00-SoftWare\Python3.11\Lib\site-packages\django\db\models\query.py", line 424, in get
    clone = self._chain() if self.query.combinator else self.filter(*args, **kwargs)
                                                        ^^^^^^^^^^^^^^^^^^^^^^^^^^^^
  File "D:\00-SoftWare\Python3.11\Lib\site-packages\django\db\models\query.py", line 941, in filter
    return self._filter_or_exclude(False, args, kwargs)
           ^^^^^^^^^^^^^^^^^^^^^^^^^^^^^^^^^^^^^^^^^^^^
  File "D:\00-SoftWare\Python3.11\Lib\site-packages\django\db\models\query.py", line 961, in _filter_or_exclude
    clone._filter_or_exclude_inplace(negate, args, kwargs)
  File "D:\00-SoftWare\Python3.11\Lib\site-packages\django\db\models\query.py", line 968, in _filter_or_exclude_inplace
    self._query.add_q(Q(*args, **kwargs))
  File "D:\00-SoftWare\Python3.11\Lib\site-packages\django\db\models\sql\query.py", line 1391, in add_q
    clause, _ = self._add_q(q_object, self.used_aliases)
                ^^^^^^^^^^^^^^^^^^^^^^^^^^^^^^^^^^^^^^^^
  File "D:\00-SoftWare\Python3.11\Lib\site-packages\django\db\models\sql\query.py", line 1410, in _add_q
    child_clause, needed_inner = self.build_filter(
                                 ^^^^^^^^^^^^^^^^^^
  File "D:\00-SoftWare\Python3.11\Lib\site-packages\django\db\models\sql\query.py", line 1345, in build_filter
    condition = self.build_lookup(lookups, col, value)
                ^^^^^^^^^^^^^^^^^^^^^^^^^^^^^^^^^^^^^^
  File "D:\00-SoftWare\Python3.11\Lib\site-packages\django\db\models\sql\query.py", line 1191, in build_lookup
    lookup = lookup_class(lhs, rhs)
             ^^^^^^^^^^^^^^^^^^^^^^
  File "D:\00-SoftWare\Python3.11\Lib\site-packages\django\db\models\lookups.py", line 25, in __init__
    self.rhs = self.get_prep_lookup()
               ^^^^^^^^^^^^^^^^^^^^^^
  File "D:\00-SoftWare\Python3.11\Lib\site-packages\django\db\models\lookups.py", line 77, in get_prep_lookup
    return self.lhs.output_field.get_prep_value(self.rhs)
           ^^^^^^^^^^^^^^^^^^^^^^^^^^^^^^^^^^^^^^^^^^^^^^
  File "D:\00-SoftWare\Python3.11\Lib\site-packages\django\db\models\fields\__init__.py", line 1825, in get_prep_value
    raise e.__class__(
ValueError: Field 'id' expected a number but got 'search_by_online_version'.

During handling of the above exception, another exception occurred:

Traceback (most recent call last):
  File "D:\00-SoftWare\Python3.11\Lib\site-packages\rest_framework\views.py", line 506, in dispatch
    response = handler(request, *args, **kwargs)
               ^^^^^^^^^^^^^^^^^^^^^^^^^^^^^^^^^
  File "F:\django-vue-admin\backend\dvadmin\utils\viewset.py", line 88, in retrieve
    instance = self.get_object()
               ^^^^^^^^^^^^^^^^^
  File "D:\00-SoftWare\Python3.11\Lib\site-packages\rest_framework\generics.py", line 96, in get_object
    obj = get_object_or_404(queryset, **filter_kwargs)
          ^^^^^^^^^^^^^^^^^^^^^^^^^^^^^^^^^^^^^^^^^^^^
  File "D:\00-SoftWare\Python3.11\Lib\site-packages\rest_framework\generics.py", line 21, in get_object_or_404
    raise Http404
django.http.response.Http404

